2025-04-21 16:49:55,299 - INFO - __main__ - Logging to file enabled
2025-04-21 16:49:59,568 - INFO - __main__ - Logging to file enabled
2025-04-21 16:50:13,507 - ERROR - __main__ - Unhandled exception: 404 Not Found: The requested URL was not found on the server. If you entered the URL manually please check your spelling and try again.
2025-04-21 16:50:13,510 - ERROR - __main__ - Traceback: Traceback (most recent call last):
  File "/home/olex/.local/lib/python3.8/site-packages/flask/app.py", line 1823, in full_dispatch_request
    rv = self.dispatch_request()
  File "/home/olex/.local/lib/python3.8/site-packages/flask/app.py", line 1799, in dispatch_request
    return self.ensure_sync(self.view_functions[rule.endpoint])(**view_args)
  File "/home/olex/.local/lib/python3.8/site-packages/flask/app.py", line 713, in <lambda>
    view_func=lambda **kw: self_ref().send_static_file(**kw),  # type: ignore # noqa: B950
  File "/home/olex/.local/lib/python3.8/site-packages/flask/scaffold.py", line 331, in send_static_file
    return send_from_directory(
  File "/home/olex/.local/lib/python3.8/site-packages/flask/helpers.py", line 590, in send_from_directory
    return werkzeug.utils.send_from_directory(  # type: ignore[return-value]
  File "/home/olex/.local/lib/python3.8/site-packages/werkzeug/utils.py", line 587, in send_from_directory
    raise NotFound()
werkzeug.exceptions.NotFound: 404 Not Found: The requested URL was not found on the server. If you entered the URL manually please check your spelling and try again.

2025-04-21 16:50:13,523 - ERROR - __main__ - Unhandled exception: 404 Not Found: The requested URL was not found on the server. If you entered the URL manually please check your spelling and try again.
2025-04-21 16:50:13,525 - ERROR - __main__ - Traceback: Traceback (most recent call last):
  File "/home/olex/.local/lib/python3.8/site-packages/flask/app.py", line 1823, in full_dispatch_request
    rv = self.dispatch_request()
  File "/home/olex/.local/lib/python3.8/site-packages/flask/app.py", line 1799, in dispatch_request
    return self.ensure_sync(self.view_functions[rule.endpoint])(**view_args)
  File "/home/olex/.local/lib/python3.8/site-packages/flask/app.py", line 713, in <lambda>
    view_func=lambda **kw: self_ref().send_static_file(**kw),  # type: ignore # noqa: B950
  File "/home/olex/.local/lib/python3.8/site-packages/flask/scaffold.py", line 331, in send_static_file
    return send_from_directory(
  File "/home/olex/.local/lib/python3.8/site-packages/flask/helpers.py", line 590, in send_from_directory
    return werkzeug.utils.send_from_directory(  # type: ignore[return-value]
  File "/home/olex/.local/lib/python3.8/site-packages/werkzeug/utils.py", line 587, in send_from_directory
    raise NotFound()
werkzeug.exceptions.NotFound: 404 Not Found: The requested URL was not found on the server. If you entered the URL manually please check your spelling and try again.

2025-04-21 16:50:13,528 - ERROR - __main__ - Unhandled exception: 404 Not Found: The requested URL was not found on the server. If you entered the URL manually please check your spelling and try again.
2025-04-21 16:50:13,530 - ERROR - __main__ - Unhandled exception: 404 Not Found: The requested URL was not found on the server. If you entered the URL manually please check your spelling and try again.
2025-04-21 16:50:13,530 - ERROR - __main__ - Traceback: Traceback (most recent call last):
  File "/home/olex/.local/lib/python3.8/site-packages/flask/app.py", line 1823, in full_dispatch_request
    rv = self.dispatch_request()
  File "/home/olex/.local/lib/python3.8/site-packages/flask/app.py", line 1799, in dispatch_request
    return self.ensure_sync(self.view_functions[rule.endpoint])(**view_args)
  File "/home/olex/.local/lib/python3.8/site-packages/flask/app.py", line 713, in <lambda>
    view_func=lambda **kw: self_ref().send_static_file(**kw),  # type: ignore # noqa: B950
  File "/home/olex/.local/lib/python3.8/site-packages/flask/scaffold.py", line 331, in send_static_file
    return send_from_directory(
  File "/home/olex/.local/lib/python3.8/site-packages/flask/helpers.py", line 590, in send_from_directory
    return werkzeug.utils.send_from_directory(  # type: ignore[return-value]
  File "/home/olex/.local/lib/python3.8/site-packages/werkzeug/utils.py", line 587, in send_from_directory
    raise NotFound()
werkzeug.exceptions.NotFound: 404 Not Found: The requested URL was not found on the server. If you entered the URL manually please check your spelling and try again.

2025-04-21 16:50:13,532 - ERROR - __main__ - Traceback: Traceback (most recent call last):
  File "/home/olex/.local/lib/python3.8/site-packages/flask/app.py", line 1823, in full_dispatch_request
    rv = self.dispatch_request()
  File "/home/olex/.local/lib/python3.8/site-packages/flask/app.py", line 1799, in dispatch_request
    return self.ensure_sync(self.view_functions[rule.endpoint])(**view_args)
  File "/home/olex/.local/lib/python3.8/site-packages/flask/app.py", line 713, in <lambda>
    view_func=lambda **kw: self_ref().send_static_file(**kw),  # type: ignore # noqa: B950
  File "/home/olex/.local/lib/python3.8/site-packages/flask/scaffold.py", line 331, in send_static_file
    return send_from_directory(
  File "/home/olex/.local/lib/python3.8/site-packages/flask/helpers.py", line 590, in send_from_directory
    return werkzeug.utils.send_from_directory(  # type: ignore[return-value]
  File "/home/olex/.local/lib/python3.8/site-packages/werkzeug/utils.py", line 587, in send_from_directory
    raise NotFound()
werkzeug.exceptions.NotFound: 404 Not Found: The requested URL was not found on the server. If you entered the URL manually please check your spelling and try again.

2025-04-21 16:55:47,917 - INFO - __main__ - Logging to file enabled
2025-04-21 16:55:54,763 - INFO - __main__ - Logging to file enabled
2025-04-21 16:56:36,300 - ERROR - __main__ - Error getting memory info: No module named 'psutil'
2025-04-21 16:57:33,184 - INFO - __main__ - Logging to file enabled
2025-04-21 16:57:37,368 - INFO - __main__ - Logging to file enabled
2025-04-21 16:58:26,810 - INFO - __main__ - Starting simplified training endpoint
2025-04-21 16:58:26,811 - INFO - __main__ - Initializing ModelTrainer
2025-04-21 16:58:26,816 - INFO - __main__ - Loading data from data_loader
2025-04-21 16:58:28,392 - INFO - __main__ - Loaded 18738 rows of data
2025-04-21 16:58:28,393 - INFO - __main__ - Sample data columns: ['timestamp', 'open', 'high', 'low', 'close', 'volume', 'vwap']
2025-04-21 16:58:28,395 - INFO - __main__ - Sample data types: timestamp    datetime64[ns, pytz.FixedOffset(-240)]
open                                        float64
high                                        float64
low                                         float64
close                                       float64
volume                                      float64
vwap                                        float64
dtype: object
2025-04-21 16:58:28,395 - INFO - __main__ - Generating features
2025-04-21 16:58:28,601 - INFO - __main__ - Generated features for 18738 rows
2025-04-21 16:58:28,602 - INFO - __main__ - Processed data columns: ['timestamp', 'open', 'high', 'low', 'close', 'volume', 'vwap', 'sma_5', 'sma_20', 'ema_5', 'ema_20', 'rsi', 'macd', 'macd_signal', 'macd_diff', 'bb_middle', 'bb_upper', 'bb_lower', 'price_change', 'price_change_5', 'volume_change', 'volume_ma_5']
2025-04-21 16:58:28,604 - INFO - __main__ - Preparing training data
2025-04-21 17:08:00,085 - INFO - __main__ - Logging to file enabled
2025-04-21 17:08:04,548 - INFO - __main__ - Logging to file enabled
2025-04-21 17:08:22,115 - ERROR - __main__ - Unhandled exception: 404 Not Found: The requested URL was not found on the server. If you entered the URL manually please check your spelling and try again.
2025-04-21 17:08:22,120 - ERROR - __main__ - Traceback: Traceback (most recent call last):
  File "/home/olex/.local/lib/python3.8/site-packages/flask/app.py", line 1823, in full_dispatch_request
    rv = self.dispatch_request()
  File "/home/olex/.local/lib/python3.8/site-packages/flask/app.py", line 1788, in dispatch_request
    self.raise_routing_exception(req)
  File "/home/olex/.local/lib/python3.8/site-packages/flask/app.py", line 1770, in raise_routing_exception
    raise request.routing_exception  # type: ignore
  File "/home/olex/.local/lib/python3.8/site-packages/flask/ctx.py", line 351, in match_request
    result = self.url_adapter.match(return_rule=True)  # type: ignore
  File "/home/olex/.local/lib/python3.8/site-packages/werkzeug/routing/map.py", line 624, in match
    raise NotFound() from None
werkzeug.exceptions.NotFound: 404 Not Found: The requested URL was not found on the server. If you entered the URL manually please check your spelling and try again.

2025-04-21 17:14:25,478 - INFO - __main__ - Logging to file enabled
2025-04-21 17:14:29,448 - INFO - __main__ - Logging to file enabled
2025-04-21 17:14:38,661 - ERROR - __main__ - Unhandled exception: 404 Not Found: The requested URL was not found on the server. If you entered the URL manually please check your spelling and try again.
2025-04-21 17:14:38,665 - ERROR - __main__ - Traceback: Traceback (most recent call last):
  File "/home/olex/.local/lib/python3.8/site-packages/flask/app.py", line 1823, in full_dispatch_request
    rv = self.dispatch_request()
  File "/home/olex/.local/lib/python3.8/site-packages/flask/app.py", line 1788, in dispatch_request
    self.raise_routing_exception(req)
  File "/home/olex/.local/lib/python3.8/site-packages/flask/app.py", line 1770, in raise_routing_exception
    raise request.routing_exception  # type: ignore
  File "/home/olex/.local/lib/python3.8/site-packages/flask/ctx.py", line 351, in match_request
    result = self.url_adapter.match(return_rule=True)  # type: ignore
  File "/home/olex/.local/lib/python3.8/site-packages/werkzeug/routing/map.py", line 624, in match
    raise NotFound() from None
werkzeug.exceptions.NotFound: 404 Not Found: The requested URL was not found on the server. If you entered the URL manually please check your spelling and try again.

2025-04-21 17:14:41,594 - ERROR - __main__ - Unhandled exception: 404 Not Found: The requested URL was not found on the server. If you entered the URL manually please check your spelling and try again.
2025-04-21 17:14:41,595 - ERROR - __main__ - Traceback: Traceback (most recent call last):
  File "/home/olex/.local/lib/python3.8/site-packages/flask/app.py", line 1823, in full_dispatch_request
    rv = self.dispatch_request()
  File "/home/olex/.local/lib/python3.8/site-packages/flask/app.py", line 1788, in dispatch_request
    self.raise_routing_exception(req)
  File "/home/olex/.local/lib/python3.8/site-packages/flask/app.py", line 1770, in raise_routing_exception
    raise request.routing_exception  # type: ignore
  File "/home/olex/.local/lib/python3.8/site-packages/flask/ctx.py", line 351, in match_request
    result = self.url_adapter.match(return_rule=True)  # type: ignore
  File "/home/olex/.local/lib/python3.8/site-packages/werkzeug/routing/map.py", line 624, in match
    raise NotFound() from None
werkzeug.exceptions.NotFound: 404 Not Found: The requested URL was not found on the server. If you entered the URL manually please check your spelling and try again.

2025-04-21 17:15:00,763 - ERROR - __main__ - Unhandled exception: 404 Not Found: The requested URL was not found on the server. If you entered the URL manually please check your spelling and try again.
2025-04-21 17:15:00,765 - ERROR - __main__ - Traceback: Traceback (most recent call last):
  File "/home/olex/.local/lib/python3.8/site-packages/flask/app.py", line 1823, in full_dispatch_request
    rv = self.dispatch_request()
  File "/home/olex/.local/lib/python3.8/site-packages/flask/app.py", line 1788, in dispatch_request
    self.raise_routing_exception(req)
  File "/home/olex/.local/lib/python3.8/site-packages/flask/app.py", line 1770, in raise_routing_exception
    raise request.routing_exception  # type: ignore
  File "/home/olex/.local/lib/python3.8/site-packages/flask/ctx.py", line 351, in match_request
    result = self.url_adapter.match(return_rule=True)  # type: ignore
  File "/home/olex/.local/lib/python3.8/site-packages/werkzeug/routing/map.py", line 624, in match
    raise NotFound() from None
werkzeug.exceptions.NotFound: 404 Not Found: The requested URL was not found on the server. If you entered the URL manually please check your spelling and try again.

2025-04-21 17:15:19,492 - INFO - __main__ - Initializing ModelTrainer
2025-04-21 17:15:19,498 - INFO - __main__ - Created test data X: (100, 60, 20), y: (100, 10)
2025-04-21 17:15:19,499 - INFO - __main__ - Initializing models with input shape: (60, 20)
2025-04-21 17:15:19,502 - INFO - __main__ - Models initialized successfully
2025-04-21 17:15:19,503 - INFO - __main__ - Setting up TensorFlow
2025-04-21 17:15:19,503 - INFO - __main__ - No GPUs found, using CPU
2025-04-21 17:15:19,504 - INFO - __main__ - Enabling mixed precision
2025-04-21 17:15:19,506 - INFO - __main__ - Training data prepared
2025-04-21 17:15:19,507 - INFO - __main__ - X_train: (80, 60, 20), y_train: (80, 10)
2025-04-21 17:15:19,507 - INFO - __main__ - X_val: (20, 60, 20), y_val: (20, 10)
2025-04-21 17:15:19,508 - INFO - __main__ - Building model
2025-04-21 17:15:20,367 - INFO - __main__ - Setting batch size to 4
2025-04-21 17:15:20,368 - INFO - __main__ - Starting model training
2025-04-21 17:15:34,840 - INFO - __main__ - Logging to file enabled
2025-04-21 17:18:23,903 - INFO - __main__ - Logging to file enabled
2025-04-21 17:18:36,268 - ERROR - __main__ - Unhandled exception: 404 Not Found: The requested URL was not found on the server. If you entered the URL manually please check your spelling and try again.
2025-04-21 17:18:36,271 - ERROR - __main__ - Traceback: Traceback (most recent call last):
  File "/home/olex/.local/lib/python3.8/site-packages/flask/app.py", line 1823, in full_dispatch_request
    rv = self.dispatch_request()
  File "/home/olex/.local/lib/python3.8/site-packages/flask/app.py", line 1788, in dispatch_request
    self.raise_routing_exception(req)
  File "/home/olex/.local/lib/python3.8/site-packages/flask/app.py", line 1770, in raise_routing_exception
    raise request.routing_exception  # type: ignore
  File "/home/olex/.local/lib/python3.8/site-packages/flask/ctx.py", line 351, in match_request
    result = self.url_adapter.match(return_rule=True)  # type: ignore
  File "/home/olex/.local/lib/python3.8/site-packages/werkzeug/routing/map.py", line 624, in match
    raise NotFound() from None
werkzeug.exceptions.NotFound: 404 Not Found: The requested URL was not found on the server. If you entered the URL manually please check your spelling and try again.

2025-04-21 17:19:48,689 - ERROR - __main__ - Unhandled exception: 404 Not Found: The requested URL was not found on the server. If you entered the URL manually please check your spelling and try again.
2025-04-21 17:19:48,690 - ERROR - __main__ - Traceback: Traceback (most recent call last):
  File "/home/olex/.local/lib/python3.8/site-packages/flask/app.py", line 1823, in full_dispatch_request
    rv = self.dispatch_request()
  File "/home/olex/.local/lib/python3.8/site-packages/flask/app.py", line 1788, in dispatch_request
    self.raise_routing_exception(req)
  File "/home/olex/.local/lib/python3.8/site-packages/flask/app.py", line 1770, in raise_routing_exception
    raise request.routing_exception  # type: ignore
  File "/home/olex/.local/lib/python3.8/site-packages/flask/ctx.py", line 351, in match_request
    result = self.url_adapter.match(return_rule=True)  # type: ignore
  File "/home/olex/.local/lib/python3.8/site-packages/werkzeug/routing/map.py", line 624, in match
    raise NotFound() from None
werkzeug.exceptions.NotFound: 404 Not Found: The requested URL was not found on the server. If you entered the URL manually please check your spelling and try again.

2025-04-21 17:21:42,434 - INFO - __main__ - Initializing ModelTrainer
2025-04-21 17:21:42,441 - INFO - __main__ - Created test data X: (100, 60, 20), y: (100, 10)
2025-04-21 17:21:42,441 - INFO - __main__ - Initializing models with input shape: (60, 20)
2025-04-21 17:21:42,445 - INFO - __main__ - Models initialized successfully
2025-04-21 17:21:42,446 - INFO - __main__ - Setting up TensorFlow
2025-04-21 17:21:42,446 - INFO - __main__ - No GPUs found, using CPU
2025-04-21 17:21:42,447 - INFO - __main__ - Enabling mixed precision
2025-04-21 17:21:42,449 - INFO - __main__ - Training data prepared
2025-04-21 17:21:42,449 - INFO - __main__ - X_train: (80, 60, 20), y_train: (80, 10)
2025-04-21 17:21:42,450 - INFO - __main__ - X_val: (20, 60, 20), y_val: (20, 10)
2025-04-21 17:21:42,450 - INFO - __main__ - Building model
2025-04-21 17:21:43,223 - INFO - __main__ - Setting batch size to 4
2025-04-21 17:21:43,223 - INFO - __main__ - Starting model training
2025-04-21 17:21:54,813 - INFO - __main__ - Model training completed successfully
2025-04-21 17:21:54,814 - INFO - __main__ - Validation loss: 0.20905761420726776
2025-04-21 17:21:54,814 - ERROR - __main__ - Error during simplified training: save() takes 1 positional argument but 2 were given
2025-04-21 17:21:54,818 - ERROR - __main__ - Traceback: Traceback (most recent call last):
  File "app.py", line 531, in simplified_training
    model.save("simplified_test")
TypeError: save() takes 1 positional argument but 2 were given

2025-04-21 17:24:23,082 - INFO - __main__ - Logging to file enabled
2025-04-21 17:24:28,660 - ERROR - __main__ - Unhandled exception: 404 Not Found: The requested URL was not found on the server. If you entered the URL manually please check your spelling and try again.
2025-04-21 17:24:28,662 - ERROR - __main__ - Traceback: Traceback (most recent call last):
  File "/home/olex/.local/lib/python3.8/site-packages/flask/app.py", line 1823, in full_dispatch_request
    rv = self.dispatch_request()
  File "/home/olex/.local/lib/python3.8/site-packages/flask/app.py", line 1788, in dispatch_request
    self.raise_routing_exception(req)
  File "/home/olex/.local/lib/python3.8/site-packages/flask/app.py", line 1770, in raise_routing_exception
    raise request.routing_exception  # type: ignore
  File "/home/olex/.local/lib/python3.8/site-packages/flask/ctx.py", line 351, in match_request
    result = self.url_adapter.match(return_rule=True)  # type: ignore
  File "/home/olex/.local/lib/python3.8/site-packages/werkzeug/routing/map.py", line 624, in match
    raise NotFound() from None
werkzeug.exceptions.NotFound: 404 Not Found: The requested URL was not found on the server. If you entered the URL manually please check your spelling and try again.

2025-04-21 17:24:30,697 - ERROR - __main__ - Unhandled exception: 404 Not Found: The requested URL was not found on the server. If you entered the URL manually please check your spelling and try again.
2025-04-21 17:24:30,698 - ERROR - __main__ - Traceback: Traceback (most recent call last):
  File "/home/olex/.local/lib/python3.8/site-packages/flask/app.py", line 1823, in full_dispatch_request
    rv = self.dispatch_request()
  File "/home/olex/.local/lib/python3.8/site-packages/flask/app.py", line 1788, in dispatch_request
    self.raise_routing_exception(req)
  File "/home/olex/.local/lib/python3.8/site-packages/flask/app.py", line 1770, in raise_routing_exception
    raise request.routing_exception  # type: ignore
  File "/home/olex/.local/lib/python3.8/site-packages/flask/ctx.py", line 351, in match_request
    result = self.url_adapter.match(return_rule=True)  # type: ignore
  File "/home/olex/.local/lib/python3.8/site-packages/werkzeug/routing/map.py", line 624, in match
    raise NotFound() from None
werkzeug.exceptions.NotFound: 404 Not Found: The requested URL was not found on the server. If you entered the URL manually please check your spelling and try again.

2025-04-21 17:24:38,265 - ERROR - __main__ - Unhandled exception: 404 Not Found: The requested URL was not found on the server. If you entered the URL manually please check your spelling and try again.
2025-04-21 17:24:38,266 - ERROR - __main__ - Traceback: Traceback (most recent call last):
  File "/home/olex/.local/lib/python3.8/site-packages/flask/app.py", line 1823, in full_dispatch_request
    rv = self.dispatch_request()
  File "/home/olex/.local/lib/python3.8/site-packages/flask/app.py", line 1788, in dispatch_request
    self.raise_routing_exception(req)
  File "/home/olex/.local/lib/python3.8/site-packages/flask/app.py", line 1770, in raise_routing_exception
    raise request.routing_exception  # type: ignore
  File "/home/olex/.local/lib/python3.8/site-packages/flask/ctx.py", line 351, in match_request
    result = self.url_adapter.match(return_rule=True)  # type: ignore
  File "/home/olex/.local/lib/python3.8/site-packages/werkzeug/routing/map.py", line 624, in match
    raise NotFound() from None
werkzeug.exceptions.NotFound: 404 Not Found: The requested URL was not found on the server. If you entered the URL manually please check your spelling and try again.

2025-04-21 17:24:41,055 - INFO - __main__ - Initializing ModelTrainer
2025-04-21 17:24:41,061 - INFO - __main__ - Created test data X: (100, 60, 20), y: (100, 10)
2025-04-21 17:24:41,062 - INFO - __main__ - Initializing models with input shape: (60, 20)
2025-04-21 17:24:41,065 - INFO - __main__ - Models initialized successfully
2025-04-21 17:24:41,066 - INFO - __main__ - Setting up TensorFlow
2025-04-21 17:24:41,066 - INFO - __main__ - No GPUs found, using CPU
2025-04-21 17:24:41,067 - INFO - __main__ - Enabling mixed precision
2025-04-21 17:24:41,068 - INFO - __main__ - Training data prepared
2025-04-21 17:24:41,069 - INFO - __main__ - X_train: (80, 60, 20), y_train: (80, 10)
2025-04-21 17:24:41,069 - INFO - __main__ - X_val: (20, 60, 20), y_val: (20, 10)
2025-04-21 17:24:41,070 - INFO - __main__ - Building model
2025-04-21 17:24:41,746 - INFO - __main__ - Setting batch size to 4
2025-04-21 17:24:41,747 - INFO - __main__ - Starting model training
2025-04-21 17:24:53,442 - INFO - __main__ - Model training completed successfully
2025-04-21 17:24:53,443 - INFO - __main__ - Validation loss: 0.24089355766773224
2025-04-21 17:26:29,975 - ERROR - __main__ - Unhandled exception: 404 Not Found: The requested URL was not found on the server. If you entered the URL manually please check your spelling and try again.
2025-04-21 17:26:29,976 - ERROR - __main__ - Traceback: Traceback (most recent call last):
  File "/home/olex/.local/lib/python3.8/site-packages/flask/app.py", line 1823, in full_dispatch_request
    rv = self.dispatch_request()
  File "/home/olex/.local/lib/python3.8/site-packages/flask/app.py", line 1788, in dispatch_request
    self.raise_routing_exception(req)
  File "/home/olex/.local/lib/python3.8/site-packages/flask/app.py", line 1770, in raise_routing_exception
    raise request.routing_exception  # type: ignore
  File "/home/olex/.local/lib/python3.8/site-packages/flask/ctx.py", line 351, in match_request
    result = self.url_adapter.match(return_rule=True)  # type: ignore
  File "/home/olex/.local/lib/python3.8/site-packages/werkzeug/routing/map.py", line 624, in match
    raise NotFound() from None
werkzeug.exceptions.NotFound: 404 Not Found: The requested URL was not found on the server. If you entered the URL manually please check your spelling and try again.

2025-04-21 17:26:31,282 - ERROR - __main__ - Unhandled exception: 404 Not Found: The requested URL was not found on the server. If you entered the URL manually please check your spelling and try again.
2025-04-21 17:26:31,318 - ERROR - __main__ - Traceback: Traceback (most recent call last):
  File "/home/olex/.local/lib/python3.8/site-packages/flask/app.py", line 1823, in full_dispatch_request
    rv = self.dispatch_request()
  File "/home/olex/.local/lib/python3.8/site-packages/flask/app.py", line 1788, in dispatch_request
    self.raise_routing_exception(req)
  File "/home/olex/.local/lib/python3.8/site-packages/flask/app.py", line 1770, in raise_routing_exception
    raise request.routing_exception  # type: ignore
  File "/home/olex/.local/lib/python3.8/site-packages/flask/ctx.py", line 351, in match_request
    result = self.url_adapter.match(return_rule=True)  # type: ignore
  File "/home/olex/.local/lib/python3.8/site-packages/werkzeug/routing/map.py", line 624, in match
    raise NotFound() from None
werkzeug.exceptions.NotFound: 404 Not Found: The requested URL was not found on the server. If you entered the URL manually please check your spelling and try again.

2025-04-21 17:26:38,603 - INFO - __main__ - Features generated successfully for 16933 rows
2025-04-21 17:26:38,605 - INFO - __main__ - Preparing training data
2025-04-21 17:26:52,570 - ERROR - __main__ - Unhandled exception: 404 Not Found: The requested URL was not found on the server. If you entered the URL manually please check your spelling and try again.
2025-04-21 17:26:52,813 - ERROR - __main__ - Traceback: Traceback (most recent call last):
  File "/home/olex/.local/lib/python3.8/site-packages/flask/app.py", line 1823, in full_dispatch_request
    rv = self.dispatch_request()
  File "/home/olex/.local/lib/python3.8/site-packages/flask/app.py", line 1788, in dispatch_request
    self.raise_routing_exception(req)
  File "/home/olex/.local/lib/python3.8/site-packages/flask/app.py", line 1770, in raise_routing_exception
    raise request.routing_exception  # type: ignore
  File "/home/olex/.local/lib/python3.8/site-packages/flask/ctx.py", line 351, in match_request
    result = self.url_adapter.match(return_rule=True)  # type: ignore
  File "/home/olex/.local/lib/python3.8/site-packages/werkzeug/routing/map.py", line 624, in match
    raise NotFound() from None
werkzeug.exceptions.NotFound: 404 Not Found: The requested URL was not found on the server. If you entered the URL manually please check your spelling and try again.

2025-04-21 17:27:03,232 - ERROR - __main__ - Unhandled exception: 404 Not Found: The requested URL was not found on the server. If you entered the URL manually please check your spelling and try again.
2025-04-21 17:27:03,255 - ERROR - __main__ - Traceback: Traceback (most recent call last):
  File "/home/olex/.local/lib/python3.8/site-packages/flask/app.py", line 1823, in full_dispatch_request
    rv = self.dispatch_request()
  File "/home/olex/.local/lib/python3.8/site-packages/flask/app.py", line 1788, in dispatch_request
    self.raise_routing_exception(req)
  File "/home/olex/.local/lib/python3.8/site-packages/flask/app.py", line 1770, in raise_routing_exception
    raise request.routing_exception  # type: ignore
  File "/home/olex/.local/lib/python3.8/site-packages/flask/ctx.py", line 351, in match_request
    result = self.url_adapter.match(return_rule=True)  # type: ignore
  File "/home/olex/.local/lib/python3.8/site-packages/werkzeug/routing/map.py", line 624, in match
    raise NotFound() from None
werkzeug.exceptions.NotFound: 404 Not Found: The requested URL was not found on the server. If you entered the URL manually please check your spelling and try again.

2025-04-21 17:27:05,539 - ERROR - __main__ - Unhandled exception: 404 Not Found: The requested URL was not found on the server. If you entered the URL manually please check your spelling and try again.
2025-04-21 17:27:05,881 - ERROR - __main__ - Traceback: Traceback (most recent call last):
  File "/home/olex/.local/lib/python3.8/site-packages/flask/app.py", line 1823, in full_dispatch_request
    rv = self.dispatch_request()
  File "/home/olex/.local/lib/python3.8/site-packages/flask/app.py", line 1788, in dispatch_request
    self.raise_routing_exception(req)
  File "/home/olex/.local/lib/python3.8/site-packages/flask/app.py", line 1770, in raise_routing_exception
    raise request.routing_exception  # type: ignore
  File "/home/olex/.local/lib/python3.8/site-packages/flask/ctx.py", line 351, in match_request
    result = self.url_adapter.match(return_rule=True)  # type: ignore
  File "/home/olex/.local/lib/python3.8/site-packages/werkzeug/routing/map.py", line 624, in match
    raise NotFound() from None
werkzeug.exceptions.NotFound: 404 Not Found: The requested URL was not found on the server. If you entered the URL manually please check your spelling and try again.

2025-04-21 17:29:04,703 - INFO - __main__ - Logging to file enabled
2025-04-21 17:30:06,534 - ERROR - __main__ - Unhandled exception: 404 Not Found: The requested URL was not found on the server. If you entered the URL manually please check your spelling and try again.
2025-04-21 17:30:06,734 - ERROR - __main__ - Traceback: Traceback (most recent call last):
  File "/home/olex/.local/lib/python3.8/site-packages/flask/app.py", line 1823, in full_dispatch_request
    rv = self.dispatch_request()
  File "/home/olex/.local/lib/python3.8/site-packages/flask/app.py", line 1788, in dispatch_request
    self.raise_routing_exception(req)
  File "/home/olex/.local/lib/python3.8/site-packages/flask/app.py", line 1770, in raise_routing_exception
    raise request.routing_exception  # type: ignore
  File "/home/olex/.local/lib/python3.8/site-packages/flask/ctx.py", line 351, in match_request
    result = self.url_adapter.match(return_rule=True)  # type: ignore
  File "/home/olex/.local/lib/python3.8/site-packages/werkzeug/routing/map.py", line 624, in match
    raise NotFound() from None
werkzeug.exceptions.NotFound: 404 Not Found: The requested URL was not found on the server. If you entered the URL manually please check your spelling and try again.

2025-04-21 17:30:11,390 - INFO - __main__ - Initializing ModelTrainer
2025-04-21 17:30:13,341 - INFO - __main__ - Features generated successfully for 18738 rows
2025-04-21 17:30:13,342 - INFO - __main__ - Preparing training data
2025-04-21 17:44:25,736 - INFO - __main__ - Logging to file enabled
2025-04-21 17:46:42,741 - ERROR - __main__ - Unhandled exception: 404 Not Found: The requested URL was not found on the server. If you entered the URL manually please check your spelling and try again.
2025-04-21 17:46:42,764 - ERROR - __main__ - Traceback: Traceback (most recent call last):
  File "/home/olex/.local/lib/python3.8/site-packages/flask/app.py", line 1823, in full_dispatch_request
    rv = self.dispatch_request()
  File "/home/olex/.local/lib/python3.8/site-packages/flask/app.py", line 1788, in dispatch_request
    self.raise_routing_exception(req)
  File "/home/olex/.local/lib/python3.8/site-packages/flask/app.py", line 1770, in raise_routing_exception
    raise request.routing_exception  # type: ignore
  File "/home/olex/.local/lib/python3.8/site-packages/flask/ctx.py", line 351, in match_request
    result = self.url_adapter.match(return_rule=True)  # type: ignore
  File "/home/olex/.local/lib/python3.8/site-packages/werkzeug/routing/map.py", line 624, in match
    raise NotFound() from None
werkzeug.exceptions.NotFound: 404 Not Found: The requested URL was not found on the server. If you entered the URL manually please check your spelling and try again.

2025-04-21 17:46:48,776 - ERROR - __main__ - Error getting models: 'StockPredictor' object has no attribute 'model_accuracies'
2025-04-21 17:46:55,128 - INFO - __main__ - Initializing ModelTrainer
2025-04-21 17:46:56,153 - INFO - __main__ - Features generated successfully for 16933 rows
2025-04-21 17:46:56,154 - INFO - __main__ - Preparing training data
2025-04-21 17:46:56,155 - INFO - __main__ - Limiting data from 16933 to 5000 rows to prevent memory issues
2025-04-21 17:47:09,860 - INFO - __main__ - X shape: (4931, 60, 21), y shape: (4931, 10)
2025-04-21 17:47:09,866 - INFO - __main__ - X data type: float64, y data type: float64
2025-04-21 17:47:09,931 - INFO - __main__ - Input shape: (60, 21)
2025-04-21 17:47:09,934 - INFO - __main__ - Initializing models with input shape: (60, 21)
2025-04-21 17:47:09,996 - INFO - __main__ - Models initialized successfully
2025-04-21 17:47:09,997 - ERROR - __main__ - Error initializing models: 'BayesianNeuralNetwork' object has no attribute 'epochs'
2025-04-21 17:47:10,127 - ERROR - __main__ - Traceback: Traceback (most recent call last):
  File "app.py", line 304, in start_training
    original_epochs = model.epochs
AttributeError: 'BayesianNeuralNetwork' object has no attribute 'epochs'

2025-04-21 17:51:10,996 - INFO - __main__ - Logging to file enabled
2025-04-21 17:52:43,406 - ERROR - __main__ - Unhandled exception: 404 Not Found: The requested URL was not found on the server. If you entered the URL manually please check your spelling and try again.
2025-04-21 17:52:43,447 - ERROR - __main__ - Traceback: Traceback (most recent call last):
  File "/home/olex/.local/lib/python3.8/site-packages/flask/app.py", line 1823, in full_dispatch_request
    rv = self.dispatch_request()
  File "/home/olex/.local/lib/python3.8/site-packages/flask/app.py", line 1788, in dispatch_request
    self.raise_routing_exception(req)
  File "/home/olex/.local/lib/python3.8/site-packages/flask/app.py", line 1770, in raise_routing_exception
    raise request.routing_exception  # type: ignore
  File "/home/olex/.local/lib/python3.8/site-packages/flask/ctx.py", line 351, in match_request
    result = self.url_adapter.match(return_rule=True)  # type: ignore
  File "/home/olex/.local/lib/python3.8/site-packages/werkzeug/routing/map.py", line 624, in match
    raise NotFound() from None
werkzeug.exceptions.NotFound: 404 Not Found: The requested URL was not found on the server. If you entered the URL manually please check your spelling and try again.

2025-04-21 17:52:44,225 - ERROR - __main__ - Unhandled exception: 404 Not Found: The requested URL was not found on the server. If you entered the URL manually please check your spelling and try again.
2025-04-21 17:52:44,683 - ERROR - __main__ - Traceback: Traceback (most recent call last):
  File "/home/olex/.local/lib/python3.8/site-packages/flask/app.py", line 1823, in full_dispatch_request
    rv = self.dispatch_request()
  File "/home/olex/.local/lib/python3.8/site-packages/flask/app.py", line 1788, in dispatch_request
    self.raise_routing_exception(req)
  File "/home/olex/.local/lib/python3.8/site-packages/flask/app.py", line 1770, in raise_routing_exception
    raise request.routing_exception  # type: ignore
  File "/home/olex/.local/lib/python3.8/site-packages/flask/ctx.py", line 351, in match_request
    result = self.url_adapter.match(return_rule=True)  # type: ignore
  File "/home/olex/.local/lib/python3.8/site-packages/werkzeug/routing/map.py", line 624, in match
    raise NotFound() from None
werkzeug.exceptions.NotFound: 404 Not Found: The requested URL was not found on the server. If you entered the URL manually please check your spelling and try again.

2025-04-21 17:52:47,642 - INFO - __main__ - Initializing ModelTrainer
2025-04-21 17:52:49,603 - INFO - __main__ - Features generated successfully for 16933 rows
2025-04-21 17:52:49,604 - INFO - __main__ - Preparing training data
2025-04-21 17:52:49,605 - INFO - __main__ - Limiting data from 16933 to 5000 rows to prevent memory issues
2025-04-21 17:53:06,226 - INFO - __main__ - X shape: (4931, 60, 21), y shape: (4931, 10)
2025-04-21 17:53:06,237 - INFO - __main__ - X data type: float64, y data type: float64
2025-04-21 17:53:06,246 - INFO - __main__ - Input shape: (60, 21)
2025-04-21 17:53:06,248 - INFO - __main__ - Initializing models with input shape: (60, 21)
2025-04-21 17:53:06,283 - INFO - __main__ - Models initialized successfully
2025-04-21 17:53:06,300 - INFO - __main__ - Adjusting model parameters for model: BayesianNeuralNetwork
2025-04-21 17:53:06,301 - INFO - __main__ - Model doesn't have epochs attribute, only adjusting batch_size to: 16
2025-04-21 17:53:06,305 - INFO - __main__ - Reducing dataset from 4931 to 1000 for training
2025-04-21 17:53:06,307 - INFO - __main__ - Training subset shape: X: (1000, 60, 21), y: (1000, 10)
2025-04-21 17:53:06,354 - INFO - __main__ - No GPUs found, using CPU
2025-04-21 17:53:06,360 - INFO - __main__ - Training model: model1
2025-04-21 17:53:06,478 - ERROR - __main__ - Error during training: Intra op parallelism cannot be modified after initialization.
2025-04-21 17:53:06,573 - ERROR - __main__ - Traceback: Traceback (most recent call last):
  File "app.py", line 365, in start_training
    history = model.train(X_train, y_train, X_val, y_val)
  File "/mnt/f/TheTurnAroundProject/models/base_model.py", line 77, in train
    self.build_model()
  File "/mnt/f/TheTurnAroundProject/models/model1_bayesian_neural_network.py", line 50, in build_model
    tf.config.threading.set_intra_op_parallelism_threads(1)
  File "/home/olex/.local/lib/python3.8/site-packages/tensorflow/python/framework/config.py", line 118, in set_intra_op_parallelism_threads
    context.context().intra_op_parallelism_threads = num_threads
  File "/home/olex/.local/lib/python3.8/site-packages/tensorflow/python/eager/context.py", line 1826, in intra_op_parallelism_threads
    raise RuntimeError(
RuntimeError: Intra op parallelism cannot be modified after initialization.

2025-04-21 17:55:26,246 - INFO - __main__ - Logging to file enabled
2025-04-21 17:55:56,381 - INFO - __main__ - Logging to file enabled
2025-04-21 17:56:06,507 - ERROR - __main__ - Unhandled exception: 404 Not Found: The requested URL was not found on the server. If you entered the URL manually please check your spelling and try again.
2025-04-21 17:56:06,665 - ERROR - __main__ - Traceback: Traceback (most recent call last):
  File "/home/olex/.local/lib/python3.8/site-packages/flask/app.py", line 1823, in full_dispatch_request
    rv = self.dispatch_request()
  File "/home/olex/.local/lib/python3.8/site-packages/flask/app.py", line 1788, in dispatch_request
    self.raise_routing_exception(req)
  File "/home/olex/.local/lib/python3.8/site-packages/flask/app.py", line 1770, in raise_routing_exception
    raise request.routing_exception  # type: ignore
  File "/home/olex/.local/lib/python3.8/site-packages/flask/ctx.py", line 351, in match_request
    result = self.url_adapter.match(return_rule=True)  # type: ignore
  File "/home/olex/.local/lib/python3.8/site-packages/werkzeug/routing/map.py", line 624, in match
    raise NotFound() from None
werkzeug.exceptions.NotFound: 404 Not Found: The requested URL was not found on the server. If you entered the URL manually please check your spelling and try again.

2025-04-21 17:56:26,284 - INFO - __main__ - Initializing ModelTrainer
2025-04-21 17:56:27,264 - INFO - __main__ - Features generated successfully for 15344 rows
2025-04-21 17:56:27,265 - INFO - __main__ - Preparing training data
2025-04-21 17:56:27,265 - INFO - __main__ - Limiting data from 15344 to 5000 rows to prevent memory issues
2025-04-21 17:56:38,772 - INFO - __main__ - X shape: (4931, 60, 21), y shape: (4931, 10)
2025-04-21 17:56:38,796 - INFO - __main__ - X data type: float64, y data type: float64
2025-04-21 17:56:38,815 - INFO - __main__ - Input shape: (60, 21)
2025-04-21 17:56:38,815 - INFO - __main__ - Initializing models with input shape: (60, 21)
2025-04-21 17:56:38,851 - INFO - __main__ - Models initialized successfully
2025-04-21 17:56:38,851 - INFO - __main__ - Adjusting model parameters for model: BayesianNeuralNetwork
2025-04-21 17:56:38,852 - INFO - __main__ - Model doesn't have epochs attribute, only adjusting batch_size to: 16
2025-04-21 17:56:38,853 - INFO - __main__ - Reducing dataset from 4931 to 1000 for training
2025-04-21 17:56:38,853 - INFO - __main__ - Training subset shape: X: (1000, 60, 21), y: (1000, 10)
2025-04-21 17:56:38,871 - INFO - __main__ - No GPUs found, using CPU
2025-04-21 17:56:38,872 - INFO - __main__ - Training model: model1
2025-04-21 18:05:35,018 - INFO - __main__ - Logging to file enabled
2025-04-21 18:06:25,152 - ERROR - __main__ - Unhandled exception: 404 Not Found: The requested URL was not found on the server. If you entered the URL manually please check your spelling and try again.
2025-04-21 18:06:25,156 - ERROR - __main__ - Traceback: Traceback (most recent call last):
  File "/home/olex/.local/lib/python3.8/site-packages/flask/app.py", line 1823, in full_dispatch_request
    rv = self.dispatch_request()
  File "/home/olex/.local/lib/python3.8/site-packages/flask/app.py", line 1788, in dispatch_request
    self.raise_routing_exception(req)
  File "/home/olex/.local/lib/python3.8/site-packages/flask/app.py", line 1770, in raise_routing_exception
    raise request.routing_exception  # type: ignore
  File "/home/olex/.local/lib/python3.8/site-packages/flask/ctx.py", line 351, in match_request
    result = self.url_adapter.match(return_rule=True)  # type: ignore
  File "/home/olex/.local/lib/python3.8/site-packages/werkzeug/routing/map.py", line 624, in match
    raise NotFound() from None
werkzeug.exceptions.NotFound: 404 Not Found: The requested URL was not found on the server. If you entered the URL manually please check your spelling and try again.

2025-04-21 18:06:31,459 - ERROR - __main__ - Unhandled exception: 404 Not Found: The requested URL was not found on the server. If you entered the URL manually please check your spelling and try again.
2025-04-21 18:06:31,460 - ERROR - __main__ - Traceback: Traceback (most recent call last):
  File "/home/olex/.local/lib/python3.8/site-packages/flask/app.py", line 1823, in full_dispatch_request
    rv = self.dispatch_request()
  File "/home/olex/.local/lib/python3.8/site-packages/flask/app.py", line 1788, in dispatch_request
    self.raise_routing_exception(req)
  File "/home/olex/.local/lib/python3.8/site-packages/flask/app.py", line 1770, in raise_routing_exception
    raise request.routing_exception  # type: ignore
  File "/home/olex/.local/lib/python3.8/site-packages/flask/ctx.py", line 351, in match_request
    result = self.url_adapter.match(return_rule=True)  # type: ignore
  File "/home/olex/.local/lib/python3.8/site-packages/werkzeug/routing/map.py", line 624, in match
    raise NotFound() from None
werkzeug.exceptions.NotFound: 404 Not Found: The requested URL was not found on the server. If you entered the URL manually please check your spelling and try again.

2025-04-21 18:06:34,332 - INFO - __main__ - Initializing ModelTrainer
2025-04-21 18:06:35,736 - INFO - __main__ - Features generated successfully for 15344 rows
2025-04-21 18:06:35,738 - INFO - __main__ - Preparing training data
2025-04-21 18:06:35,740 - INFO - __main__ - Total data size: 15344 rows
2025-04-21 18:06:35,741 - INFO - __main__ - Fitting scalers on the entire dataset
2025-04-21 18:06:35,742 - ERROR - __main__ - Error during data preparation: name 'DATA_CONFIG' is not defined
2025-04-21 18:06:35,765 - ERROR - __main__ - Detailed traceback: Traceback (most recent call last):
  File "app.py", line 233, in start_training
    features = DATA_CONFIG.get("features", [])
NameError: name 'DATA_CONFIG' is not defined

2025-04-21 18:06:35,766 - INFO - __main__ - Trying with reduced dataset as fallback
2025-04-21 18:06:35,767 - INFO - __main__ - Creating minimal test dataset
2025-04-21 18:06:35,768 - INFO - __main__ - Creating test data with sequence_length=60, features=21
2025-04-21 18:06:35,776 - INFO - __main__ - Created test data X: (100, 60, 21), y: (100, 10)
2025-04-21 18:07:59,888 - INFO - __main__ - Logging to file enabled
2025-04-21 18:08:48,942 - INFO - __main__ - Logging to file enabled
2025-04-21 18:08:57,079 - ERROR - __main__ - Unhandled exception: 404 Not Found: The requested URL was not found on the server. If you entered the URL manually please check your spelling and try again.
2025-04-21 18:08:57,082 - ERROR - __main__ - Traceback: Traceback (most recent call last):
  File "/home/olex/.local/lib/python3.8/site-packages/flask/app.py", line 1823, in full_dispatch_request
    rv = self.dispatch_request()
  File "/home/olex/.local/lib/python3.8/site-packages/flask/app.py", line 1788, in dispatch_request
    self.raise_routing_exception(req)
  File "/home/olex/.local/lib/python3.8/site-packages/flask/app.py", line 1770, in raise_routing_exception
    raise request.routing_exception  # type: ignore
  File "/home/olex/.local/lib/python3.8/site-packages/flask/ctx.py", line 351, in match_request
    result = self.url_adapter.match(return_rule=True)  # type: ignore
  File "/home/olex/.local/lib/python3.8/site-packages/werkzeug/routing/map.py", line 624, in match
    raise NotFound() from None
werkzeug.exceptions.NotFound: 404 Not Found: The requested URL was not found on the server. If you entered the URL manually please check your spelling and try again.

2025-04-21 18:10:06,487 - ERROR - __main__ - Unhandled exception: 404 Not Found: The requested URL was not found on the server. If you entered the URL manually please check your spelling and try again.
2025-04-21 18:10:06,520 - ERROR - __main__ - Traceback: Traceback (most recent call last):
  File "/home/olex/.local/lib/python3.8/site-packages/flask/app.py", line 1823, in full_dispatch_request
    rv = self.dispatch_request()
  File "/home/olex/.local/lib/python3.8/site-packages/flask/app.py", line 1788, in dispatch_request
    self.raise_routing_exception(req)
  File "/home/olex/.local/lib/python3.8/site-packages/flask/app.py", line 1770, in raise_routing_exception
    raise request.routing_exception  # type: ignore
  File "/home/olex/.local/lib/python3.8/site-packages/flask/ctx.py", line 351, in match_request
    result = self.url_adapter.match(return_rule=True)  # type: ignore
  File "/home/olex/.local/lib/python3.8/site-packages/werkzeug/routing/map.py", line 624, in match
    raise NotFound() from None
werkzeug.exceptions.NotFound: 404 Not Found: The requested URL was not found on the server. If you entered the URL manually please check your spelling and try again.

2025-04-21 18:10:10,539 - INFO - __main__ - Initializing ModelTrainer
2025-04-21 18:10:12,065 - INFO - __main__ - Features generated successfully for 17961 rows
2025-04-21 18:10:12,075 - INFO - __main__ - Preparing training data
2025-04-21 18:10:12,077 - INFO - __main__ - Total data size: 17961 rows
2025-04-21 18:10:12,078 - INFO - __main__ - Fitting scalers on the entire dataset
2025-04-21 18:10:12,081 - ERROR - __main__ - Error during data preparation: "None of [Index(['Open', 'High', 'Low', 'Close', 'Volume', 'SMA_5', 'SMA_20', 'EMA_5',\n       'EMA_20', 'RSI', 'MACD', 'MACD_signal', 'BB_middle', 'BB_upper',\n       'BB_lower', 'Price_Change', 'Price_Change_5', 'Volume_Change',\n       'Volume_MA_5'],\n      dtype='object')] are in the [columns]"
2025-04-21 18:10:12,135 - ERROR - __main__ - Detailed traceback: Traceback (most recent call last):
  File "app.py", line 240, in start_training
    df = processed_data[features].copy()
  File "/home/olex/.local/lib/python3.8/site-packages/pandas/core/frame.py", line 3511, in __getitem__
    indexer = self.columns._get_indexer_strict(key, "columns")[1]
  File "/home/olex/.local/lib/python3.8/site-packages/pandas/core/indexes/base.py", line 5796, in _get_indexer_strict
    self._raise_if_missing(keyarr, indexer, axis_name)
  File "/home/olex/.local/lib/python3.8/site-packages/pandas/core/indexes/base.py", line 5856, in _raise_if_missing
    raise KeyError(f"None of [{key}] are in the [{axis_name}]")
KeyError: "None of [Index(['Open', 'High', 'Low', 'Close', 'Volume', 'SMA_5', 'SMA_20', 'EMA_5',\n       'EMA_20', 'RSI', 'MACD', 'MACD_signal', 'BB_middle', 'BB_upper',\n       'BB_lower', 'Price_Change', 'Price_Change_5', 'Volume_Change',\n       'Volume_MA_5'],\n      dtype='object')] are in the [columns]"

2025-04-21 18:10:12,137 - INFO - __main__ - Trying with reduced dataset as fallback
2025-04-21 18:10:12,137 - INFO - __main__ - Creating minimal test dataset
2025-04-21 18:10:12,139 - INFO - __main__ - Creating test data with sequence_length=60, features=21
2025-04-21 18:10:12,144 - INFO - __main__ - Created test data X: (100, 60, 21), y: (100, 10)
2025-04-21 18:12:06,369 - INFO - __main__ - Logging to file enabled
2025-04-21 18:13:13,568 - ERROR - __main__ - Unhandled exception: 404 Not Found: The requested URL was not found on the server. If you entered the URL manually please check your spelling and try again.
2025-04-21 18:13:13,751 - ERROR - __main__ - Traceback: Traceback (most recent call last):
  File "/home/olex/.local/lib/python3.8/site-packages/flask/app.py", line 1823, in full_dispatch_request
    rv = self.dispatch_request()
  File "/home/olex/.local/lib/python3.8/site-packages/flask/app.py", line 1788, in dispatch_request
    self.raise_routing_exception(req)
  File "/home/olex/.local/lib/python3.8/site-packages/flask/app.py", line 1770, in raise_routing_exception
    raise request.routing_exception  # type: ignore
  File "/home/olex/.local/lib/python3.8/site-packages/flask/ctx.py", line 351, in match_request
    result = self.url_adapter.match(return_rule=True)  # type: ignore
  File "/home/olex/.local/lib/python3.8/site-packages/werkzeug/routing/map.py", line 624, in match
    raise NotFound() from None
werkzeug.exceptions.NotFound: 404 Not Found: The requested URL was not found on the server. If you entered the URL manually please check your spelling and try again.

2025-04-21 18:13:16,517 - INFO - __main__ - Initializing ModelTrainer
2025-04-21 18:13:18,219 - INFO - __main__ - Features generated successfully for 18738 rows
2025-04-21 18:13:18,220 - INFO - __main__ - Preparing training data
2025-04-21 18:13:18,221 - INFO - __main__ - Total data size: 18738 rows
2025-04-21 18:13:18,223 - INFO - __main__ - Fitting scalers on the entire dataset
2025-04-21 18:13:18,232 - INFO - __main__ - Using features: ['open', 'high', 'low', 'close', 'volume', 'sma_5', 'sma_20', 'ema_5', 'ema_20', 'rsi', 'macd', 'macd_signal', 'bb_middle', 'bb_upper', 'bb_lower', 'price_change', 'price_change_5', 'volume_change', 'volume_ma_5']
2025-04-21 18:13:18,291 - INFO - __main__ - Using sequence_length=60, prediction_horizon=10
2025-04-21 18:13:18,353 - ERROR - __main__ - Error during data preparation: 'Close'
2025-04-21 18:13:18,413 - ERROR - __main__ - Detailed traceback: Traceback (most recent call last):
  File "/home/olex/.local/lib/python3.8/site-packages/pandas/core/indexes/base.py", line 3629, in get_loc
    return self._engine.get_loc(casted_key)
  File "pandas/_libs/index.pyx", line 136, in pandas._libs.index.IndexEngine.get_loc
  File "pandas/_libs/index.pyx", line 163, in pandas._libs.index.IndexEngine.get_loc
  File "pandas/_libs/hashtable_class_helper.pxi", line 5198, in pandas._libs.hashtable.PyObjectHashTable.get_item
  File "pandas/_libs/hashtable_class_helper.pxi", line 5206, in pandas._libs.hashtable.PyObjectHashTable.get_item
KeyError: 'Close'

The above exception was the direct cause of the following exception:

Traceback (most recent call last):
  File "app.py", line 310, in start_training
    X_init, y_init = create_sequences(initial_data[features])
  File "app.py", line 297, in create_sequences
    next_candles.append(scaled_data.iloc[i+sequence_length+j-1]['Close'])
  File "/home/olex/.local/lib/python3.8/site-packages/pandas/core/series.py", line 958, in __getitem__
    return self._get_value(key)
  File "/home/olex/.local/lib/python3.8/site-packages/pandas/core/series.py", line 1069, in _get_value
    loc = self.index.get_loc(label)
  File "/home/olex/.local/lib/python3.8/site-packages/pandas/core/indexes/base.py", line 3631, in get_loc
    raise KeyError(key) from err
KeyError: 'Close'

2025-04-21 18:13:18,417 - INFO - __main__ - Trying with reduced dataset as fallback
2025-04-21 18:13:18,419 - INFO - __main__ - Creating minimal test dataset
2025-04-21 18:13:18,427 - INFO - __main__ - Creating test data with sequence_length=60, features=21
2025-04-21 18:13:18,436 - INFO - __main__ - Created test data X: (100, 60, 21), y: (100, 10)
2025-04-21 18:13:18,437 - INFO - __main__ - Creating model with synthetic data as fallback
2025-04-21 18:13:21,872 - INFO - __main__ - Training model with synthetic data
2025-04-21 18:21:06,311 - INFO - __main__ - Logging to file enabled
2025-04-21 18:21:48,218 - INFO - __main__ - Logging to file enabled
2025-04-21 18:22:00,145 - ERROR - __main__ - Unhandled exception: 404 Not Found: The requested URL was not found on the server. If you entered the URL manually please check your spelling and try again.
2025-04-21 18:22:00,147 - ERROR - __main__ - Traceback: Traceback (most recent call last):
  File "/home/olex/.local/lib/python3.8/site-packages/flask/app.py", line 1823, in full_dispatch_request
    rv = self.dispatch_request()
  File "/home/olex/.local/lib/python3.8/site-packages/flask/app.py", line 1788, in dispatch_request
    self.raise_routing_exception(req)
  File "/home/olex/.local/lib/python3.8/site-packages/flask/app.py", line 1770, in raise_routing_exception
    raise request.routing_exception  # type: ignore
  File "/home/olex/.local/lib/python3.8/site-packages/flask/ctx.py", line 351, in match_request
    result = self.url_adapter.match(return_rule=True)  # type: ignore
  File "/home/olex/.local/lib/python3.8/site-packages/werkzeug/routing/map.py", line 624, in match
    raise NotFound() from None
werkzeug.exceptions.NotFound: 404 Not Found: The requested URL was not found on the server. If you entered the URL manually please check your spelling and try again.

2025-04-21 18:22:08,115 - ERROR - __main__ - Unhandled exception: 404 Not Found: The requested URL was not found on the server. If you entered the URL manually please check your spelling and try again.
2025-04-21 18:22:08,124 - ERROR - __main__ - Traceback: Traceback (most recent call last):
  File "/home/olex/.local/lib/python3.8/site-packages/flask/app.py", line 1823, in full_dispatch_request
    rv = self.dispatch_request()
  File "/home/olex/.local/lib/python3.8/site-packages/flask/app.py", line 1788, in dispatch_request
    self.raise_routing_exception(req)
  File "/home/olex/.local/lib/python3.8/site-packages/flask/app.py", line 1770, in raise_routing_exception
    raise request.routing_exception  # type: ignore
  File "/home/olex/.local/lib/python3.8/site-packages/flask/ctx.py", line 351, in match_request
    result = self.url_adapter.match(return_rule=True)  # type: ignore
  File "/home/olex/.local/lib/python3.8/site-packages/werkzeug/routing/map.py", line 624, in match
    raise NotFound() from None
werkzeug.exceptions.NotFound: 404 Not Found: The requested URL was not found on the server. If you entered the URL manually please check your spelling and try again.

2025-04-21 18:22:09,699 - INFO - __main__ - Initializing ModelTrainer
2025-04-21 18:22:11,587 - INFO - __main__ - Features generated successfully for 16933 rows
2025-04-21 18:22:11,588 - INFO - __main__ - Preparing training data
2025-04-21 18:22:11,591 - INFO - __main__ - Total data size: 16933 rows
2025-04-21 18:22:11,593 - INFO - __main__ - Fitting scalers on the entire dataset
2025-04-21 18:22:11,595 - INFO - __main__ - Using features: ['open', 'high', 'low', 'close', 'volume', 'sma_5', 'sma_20', 'ema_5', 'ema_20', 'rsi', 'macd', 'macd_signal', 'bb_middle', 'bb_upper', 'bb_lower', 'price_change', 'price_change_5', 'volume_change', 'volume_ma_5']
2025-04-21 18:22:11,657 - INFO - __main__ - Using sequence_length=60, prediction_horizon=10
2025-04-21 18:22:26,352 - INFO - __main__ - Initial X shape: (4931, 60, 19), y shape: (4931, 10)
2025-04-21 18:22:26,378 - INFO - __main__ - Input shape: (60, 19)
2025-04-21 18:22:26,379 - INFO - __main__ - Initializing models with input shape: (60, 19)
2025-04-21 18:22:26,387 - INFO - __main__ - Models initialized successfully
2025-04-21 18:22:26,390 - INFO - __main__ - Model configured with batch_size=32
2025-04-21 18:22:26,428 - INFO - __main__ - Building and compiling model
2025-04-21 18:22:29,073 - INFO - __main__ - No GPUs found, using CPU
2025-04-21 18:22:29,074 - INFO - __main__ - Processing chunk 1/3: rows 0 to 5000
2025-04-21 18:22:29,075 - INFO - __main__ - Skipping first chunk as it was used for initialization
2025-04-21 18:22:29,077 - INFO - __main__ - Processing chunk 2/3: rows 4930 to 9930
2025-04-21 18:22:42,974 - INFO - __main__ - Chunk 2 data shapes - X_train: (3944, 60, 19), y_train: (3944, 10)
2025-04-21 18:22:42,975 - INFO - __main__ - Training on chunk 2
2025-04-21 18:25:49,489 - INFO - __main__ - Chunk 2 validation - Loss: 0.04691627621650696, MAE: 0.16886253654956818
2025-04-21 18:25:50,039 - INFO - __main__ - Processing chunk 3/3: rows 9860 to 14860
2025-04-21 18:25:58,116 - INFO - __main__ - Chunk 3 data shapes - X_train: (3944, 60, 19), y_train: (3944, 10)
2025-04-21 18:25:58,117 - INFO - __main__ - Training on chunk 3
2025-04-21 18:28:32,714 - INFO - __main__ - Chunk 3 validation - Loss: 0.021415702998638153, MAE: 0.11668538302183151
2025-04-21 18:28:40,813 - INFO - __main__ - Final evaluation - Loss: 0.010561702772974968, MAE: 0.0846085324883461
2025-04-21 20:46:12,286 - INFO - __main__ - Logging to file enabled
2025-04-21 20:50:14,850 - ERROR - __main__ - Unhandled exception: 404 Not Found: The requested URL was not found on the server. If you entered the URL manually please check your spelling and try again.
2025-04-21 20:50:14,856 - ERROR - __main__ - Traceback: Traceback (most recent call last):
  File "/home/olex/.local/lib/python3.8/site-packages/flask/app.py", line 1823, in full_dispatch_request
    rv = self.dispatch_request()
  File "/home/olex/.local/lib/python3.8/site-packages/flask/app.py", line 1788, in dispatch_request
    self.raise_routing_exception(req)
  File "/home/olex/.local/lib/python3.8/site-packages/flask/app.py", line 1770, in raise_routing_exception
    raise request.routing_exception  # type: ignore
  File "/home/olex/.local/lib/python3.8/site-packages/flask/ctx.py", line 351, in match_request
    result = self.url_adapter.match(return_rule=True)  # type: ignore
  File "/home/olex/.local/lib/python3.8/site-packages/werkzeug/routing/map.py", line 624, in match
    raise NotFound() from None
werkzeug.exceptions.NotFound: 404 Not Found: The requested URL was not found on the server. If you entered the URL manually please check your spelling and try again.

2025-04-21 20:50:18,402 - ERROR - __main__ - Unhandled exception: 404 Not Found: The requested URL was not found on the server. If you entered the URL manually please check your spelling and try again.
2025-04-21 20:50:19,569 - ERROR - __main__ - Traceback: Traceback (most recent call last):
  File "/home/olex/.local/lib/python3.8/site-packages/flask/app.py", line 1823, in full_dispatch_request
    rv = self.dispatch_request()
  File "/home/olex/.local/lib/python3.8/site-packages/flask/app.py", line 1788, in dispatch_request
    self.raise_routing_exception(req)
  File "/home/olex/.local/lib/python3.8/site-packages/flask/app.py", line 1770, in raise_routing_exception
    raise request.routing_exception  # type: ignore
  File "/home/olex/.local/lib/python3.8/site-packages/flask/ctx.py", line 351, in match_request
    result = self.url_adapter.match(return_rule=True)  # type: ignore
  File "/home/olex/.local/lib/python3.8/site-packages/werkzeug/routing/map.py", line 624, in match
    raise NotFound() from None
werkzeug.exceptions.NotFound: 404 Not Found: The requested URL was not found on the server. If you entered the URL manually please check your spelling and try again.

2025-04-21 21:01:47,764 - INFO - __main__ - Logging to file enabled
2025-04-21 21:02:19,419 - ERROR - __main__ - Unhandled exception: 404 Not Found: The requested URL was not found on the server. If you entered the URL manually please check your spelling and try again.
2025-04-21 21:02:19,422 - ERROR - __main__ - Traceback: Traceback (most recent call last):
  File "/home/olex/.local/lib/python3.8/site-packages/flask/app.py", line 1823, in full_dispatch_request
    rv = self.dispatch_request()
  File "/home/olex/.local/lib/python3.8/site-packages/flask/app.py", line 1788, in dispatch_request
    self.raise_routing_exception(req)
  File "/home/olex/.local/lib/python3.8/site-packages/flask/app.py", line 1770, in raise_routing_exception
    raise request.routing_exception  # type: ignore
  File "/home/olex/.local/lib/python3.8/site-packages/flask/ctx.py", line 351, in match_request
    result = self.url_adapter.match(return_rule=True)  # type: ignore
  File "/home/olex/.local/lib/python3.8/site-packages/werkzeug/routing/map.py", line 624, in match
    raise NotFound() from None
werkzeug.exceptions.NotFound: 404 Not Found: The requested URL was not found on the server. If you entered the URL manually please check your spelling and try again.

2025-04-21 21:02:22,296 - INFO - __main__ - Initializing ModelTrainer
2025-04-21 21:02:24,229 - INFO - __main__ - Features generated successfully for 17961 rows
2025-04-21 21:02:24,230 - INFO - __main__ - Preparing training data
2025-04-21 21:02:24,231 - INFO - __main__ - Total data size: 17961 rows
2025-04-21 21:02:24,233 - INFO - __main__ - Fitting scalers on the entire dataset
2025-04-21 21:02:24,235 - INFO - __main__ - Using features: ['open', 'high', 'low', 'close', 'volume', 'sma_5', 'sma_20', 'ema_5', 'ema_20', 'rsi', 'macd', 'macd_signal', 'bb_middle', 'bb_upper', 'bb_lower', 'price_change', 'price_change_5', 'volume_change', 'volume_ma_5']
2025-04-21 21:02:24,302 - INFO - __main__ - Using sequence_length=60, prediction_horizon=10
2025-04-21 21:02:37,324 - INFO - __main__ - Initial X shape: (4931, 60, 19), y shape: (4931, 10)
2025-04-21 21:02:37,330 - INFO - __main__ - Input shape: (60, 19)
2025-04-21 21:02:37,331 - INFO - __main__ - Initializing models with input shape: (60, 19)
2025-04-21 21:02:37,333 - INFO - __main__ - Models initialized successfully
2025-04-21 21:02:37,333 - INFO - __main__ - Model configured with batch_size=32
2025-04-21 21:02:37,356 - INFO - __main__ - Building and compiling model
2025-04-21 21:02:39,569 - ERROR - __main__ - Error during data preparation: Exception encountered when calling layer "lambda" (type Lambda).

Input 'y' of 'Mul' Op has type float32 that does not match type float16 of argument 'x'.

Call arguments received by layer "lambda" (type Lambda):
  • inputs=tf.Tensor(shape=(None, 64), dtype=float16)
  • mask=None
  • training=False
2025-04-21 21:02:39,575 - ERROR - __main__ - Detailed traceback: Traceback (most recent call last):
  File "app.py", line 357, in start_training
    model.build_model()
  File "/mnt/f/TheTurnAroundProject/models/model2_bozdogan_caic.py", line 99, in build_model
    x = layers.Lambda(self._fuzzy_layer)(x)
  File "/home/olex/.local/lib/python3.8/site-packages/keras/utils/traceback_utils.py", line 67, in error_handler
    raise e.with_traceback(filtered_tb) from None
  File "/mnt/f/TheTurnAroundProject/models/model2_bozdogan_caic.py", line 150, in _fuzzy_layer
    fuzzy_values = x * fuzzy_mask + (1-fuzzy_mask) * x * 0.3
TypeError: Exception encountered when calling layer "lambda" (type Lambda).

Input 'y' of 'Mul' Op has type float32 that does not match type float16 of argument 'x'.

Call arguments received by layer "lambda" (type Lambda):
  • inputs=tf.Tensor(shape=(None, 64), dtype=float16)
  • mask=None
  • training=False

2025-04-21 21:05:12,428 - INFO - __main__ - Logging to file enabled
2025-04-21 21:05:25,276 - ERROR - __main__ - Unhandled exception: 404 Not Found: The requested URL was not found on the server. If you entered the URL manually please check your spelling and try again.
2025-04-21 21:05:25,278 - ERROR - __main__ - Traceback: Traceback (most recent call last):
  File "/home/olex/.local/lib/python3.8/site-packages/flask/app.py", line 1823, in full_dispatch_request
    rv = self.dispatch_request()
  File "/home/olex/.local/lib/python3.8/site-packages/flask/app.py", line 1788, in dispatch_request
    self.raise_routing_exception(req)
  File "/home/olex/.local/lib/python3.8/site-packages/flask/app.py", line 1770, in raise_routing_exception
    raise request.routing_exception  # type: ignore
  File "/home/olex/.local/lib/python3.8/site-packages/flask/ctx.py", line 351, in match_request
    result = self.url_adapter.match(return_rule=True)  # type: ignore
  File "/home/olex/.local/lib/python3.8/site-packages/werkzeug/routing/map.py", line 624, in match
    raise NotFound() from None
werkzeug.exceptions.NotFound: 404 Not Found: The requested URL was not found on the server. If you entered the URL manually please check your spelling and try again.

2025-04-21 21:05:36,791 - ERROR - __main__ - Unhandled exception: 404 Not Found: The requested URL was not found on the server. If you entered the URL manually please check your spelling and try again.
2025-04-21 21:05:36,793 - ERROR - __main__ - Traceback: Traceback (most recent call last):
  File "/home/olex/.local/lib/python3.8/site-packages/flask/app.py", line 1823, in full_dispatch_request
    rv = self.dispatch_request()
  File "/home/olex/.local/lib/python3.8/site-packages/flask/app.py", line 1788, in dispatch_request
    self.raise_routing_exception(req)
  File "/home/olex/.local/lib/python3.8/site-packages/flask/app.py", line 1770, in raise_routing_exception
    raise request.routing_exception  # type: ignore
  File "/home/olex/.local/lib/python3.8/site-packages/flask/ctx.py", line 351, in match_request
    result = self.url_adapter.match(return_rule=True)  # type: ignore
  File "/home/olex/.local/lib/python3.8/site-packages/werkzeug/routing/map.py", line 624, in match
    raise NotFound() from None
werkzeug.exceptions.NotFound: 404 Not Found: The requested URL was not found on the server. If you entered the URL manually please check your spelling and try again.

2025-04-21 21:05:39,374 - INFO - __main__ - Initializing ModelTrainer
2025-04-21 21:05:40,979 - INFO - __main__ - Features generated successfully for 17961 rows
2025-04-21 21:05:40,981 - INFO - __main__ - Preparing training data
2025-04-21 21:05:40,981 - INFO - __main__ - Total data size: 17961 rows
2025-04-21 21:05:40,984 - INFO - __main__ - Fitting scalers on the entire dataset
2025-04-21 21:05:40,986 - INFO - __main__ - Using features: ['open', 'high', 'low', 'close', 'volume', 'sma_5', 'sma_20', 'ema_5', 'ema_20', 'rsi', 'macd', 'macd_signal', 'bb_middle', 'bb_upper', 'bb_lower', 'price_change', 'price_change_5', 'volume_change', 'volume_ma_5']
2025-04-21 21:05:41,030 - INFO - __main__ - Using sequence_length=60, prediction_horizon=10
2025-04-21 21:05:54,481 - INFO - __main__ - Initial X shape: (4931, 60, 19), y shape: (4931, 10)
2025-04-21 21:05:54,491 - INFO - __main__ - Input shape: (60, 19)
2025-04-21 21:05:54,491 - INFO - __main__ - Initializing models with input shape: (60, 19)
2025-04-21 21:05:54,502 - INFO - __main__ - Models initialized successfully
2025-04-21 21:05:54,504 - INFO - __main__ - Model configured with batch_size=32
2025-04-21 21:05:54,536 - INFO - __main__ - Building and compiling model
2025-04-21 21:05:57,884 - INFO - __main__ - No GPUs found, using CPU
2025-04-21 21:05:57,885 - INFO - __main__ - Processing chunk 1/3: rows 0 to 5000
2025-04-21 21:05:57,889 - INFO - __main__ - Skipping first chunk as it was used for initialization
2025-04-21 21:05:57,890 - INFO - __main__ - Processing chunk 2/3: rows 4930 to 9930
2025-04-21 21:06:11,724 - INFO - __main__ - Chunk 2 data shapes - X_train: (3944, 60, 19), y_train: (3944, 10)
2025-04-21 21:06:11,728 - INFO - __main__ - Training on chunk 2
2025-04-21 21:06:28,635 - ERROR - __main__ - Error during data preparation: Input 'pred' passed int32 expected bool while building NodeDef 'BozdoganCAIC/lambda_1/cond/switch_pred/_2' using Op<name=Switch; signature=data:T, pred:bool -> output_false:T, output_true:T; attr=T:type> [Op:__inference_train_function_46504]
2025-04-21 21:06:28,648 - ERROR - __main__ - Detailed traceback: Traceback (most recent call last):
  File "app.py", line 420, in start_training
    history = model.model.fit(
  File "/home/olex/.local/lib/python3.8/site-packages/keras/utils/traceback_utils.py", line 67, in error_handler
    raise e.with_traceback(filtered_tb) from None
  File "/home/olex/.local/lib/python3.8/site-packages/tensorflow/python/eager/execute.py", line 54, in quick_execute
    tensors = pywrap_tfe.TFE_Py_Execute(ctx._handle, device_name, op_name,
tensorflow.python.framework.errors_impl.InvalidArgumentError: Input 'pred' passed int32 expected bool while building NodeDef 'BozdoganCAIC/lambda_1/cond/switch_pred/_2' using Op<name=Switch; signature=data:T, pred:bool -> output_false:T, output_true:T; attr=T:type> [Op:__inference_train_function_46504]

2025-04-21 21:09:06,821 - INFO - __main__ - Logging to file enabled
2025-04-21 21:09:24,844 - ERROR - __main__ - Unhandled exception: 404 Not Found: The requested URL was not found on the server. If you entered the URL manually please check your spelling and try again.
2025-04-21 21:09:25,008 - ERROR - __main__ - Traceback: Traceback (most recent call last):
  File "/home/olex/.local/lib/python3.8/site-packages/flask/app.py", line 1823, in full_dispatch_request
    rv = self.dispatch_request()
  File "/home/olex/.local/lib/python3.8/site-packages/flask/app.py", line 1788, in dispatch_request
    self.raise_routing_exception(req)
  File "/home/olex/.local/lib/python3.8/site-packages/flask/app.py", line 1770, in raise_routing_exception
    raise request.routing_exception  # type: ignore
  File "/home/olex/.local/lib/python3.8/site-packages/flask/ctx.py", line 351, in match_request
    result = self.url_adapter.match(return_rule=True)  # type: ignore
  File "/home/olex/.local/lib/python3.8/site-packages/werkzeug/routing/map.py", line 624, in match
    raise NotFound() from None
werkzeug.exceptions.NotFound: 404 Not Found: The requested URL was not found on the server. If you entered the URL manually please check your spelling and try again.

2025-04-21 21:09:27,470 - INFO - __main__ - Initializing ModelTrainer
2025-04-21 21:09:29,062 - INFO - __main__ - Features generated successfully for 15344 rows
2025-04-21 21:09:29,072 - INFO - __main__ - Preparing training data
2025-04-21 21:09:29,077 - INFO - __main__ - Total data size: 15344 rows
2025-04-21 21:09:29,078 - INFO - __main__ - Fitting scalers on the entire dataset
2025-04-21 21:09:29,079 - INFO - __main__ - Using features: ['open', 'high', 'low', 'close', 'volume', 'sma_5', 'sma_20', 'ema_5', 'ema_20', 'rsi', 'macd', 'macd_signal', 'bb_middle', 'bb_upper', 'bb_lower', 'price_change', 'price_change_5', 'volume_change', 'volume_ma_5']
2025-04-21 21:09:29,137 - INFO - __main__ - Using sequence_length=60, prediction_horizon=10
2025-04-21 21:09:43,397 - INFO - __main__ - Initial X shape: (4931, 60, 19), y shape: (4931, 10)
2025-04-21 21:09:43,406 - INFO - __main__ - Input shape: (60, 19)
2025-04-21 21:09:43,407 - INFO - __main__ - Initializing models with input shape: (60, 19)
2025-04-21 21:09:43,419 - INFO - __main__ - Models initialized successfully
2025-04-21 21:09:43,421 - INFO - __main__ - Model configured with batch_size=32
2025-04-21 21:09:43,447 - INFO - __main__ - Building and compiling model
2025-04-21 21:09:46,753 - INFO - __main__ - No GPUs found, using CPU
2025-04-21 21:09:46,755 - INFO - __main__ - Processing chunk 1/3: rows 0 to 5000
2025-04-21 21:09:46,766 - INFO - __main__ - Skipping first chunk as it was used for initialization
2025-04-21 21:09:46,768 - INFO - __main__ - Processing chunk 2/3: rows 4930 to 9930
2025-04-21 21:10:00,714 - INFO - __main__ - Chunk 2 data shapes - X_train: (3944, 60, 19), y_train: (3944, 10)
2025-04-21 21:10:00,716 - INFO - __main__ - Training on chunk 2
2025-04-21 21:13:23,947 - INFO - __main__ - Chunk 2 validation - Loss: 0.008301042951643467, MAE: 0.07009179890155792
2025-04-21 21:13:24,464 - INFO - __main__ - Processing chunk 3/3: rows 9860 to 14860
2025-04-21 21:13:33,234 - INFO - __main__ - Chunk 3 data shapes - X_train: (3944, 60, 19), y_train: (3944, 10)
2025-04-21 21:13:33,235 - INFO - __main__ - Training on chunk 3
2025-04-21 21:16:35,366 - INFO - __main__ - Chunk 3 validation - Loss: 0.009209053590893745, MAE: 0.07129835337400436
2025-04-21 21:16:43,882 - INFO - __main__ - Final evaluation - Loss: 0.3929011821746826, MAE: 0.6016619205474854
2025-04-21 21:23:01,321 - INFO - __main__ - Logging to file enabled
2025-04-21 21:24:06,037 - ERROR - __main__ - Unhandled exception: 404 Not Found: The requested URL was not found on the server. If you entered the URL manually please check your spelling and try again.
2025-04-21 21:24:06,259 - ERROR - __main__ - Traceback: Traceback (most recent call last):
  File "/home/olex/.local/lib/python3.8/site-packages/flask/app.py", line 1823, in full_dispatch_request
    rv = self.dispatch_request()
  File "/home/olex/.local/lib/python3.8/site-packages/flask/app.py", line 1788, in dispatch_request
    self.raise_routing_exception(req)
  File "/home/olex/.local/lib/python3.8/site-packages/flask/app.py", line 1770, in raise_routing_exception
    raise request.routing_exception  # type: ignore
  File "/home/olex/.local/lib/python3.8/site-packages/flask/ctx.py", line 351, in match_request
    result = self.url_adapter.match(return_rule=True)  # type: ignore
  File "/home/olex/.local/lib/python3.8/site-packages/werkzeug/routing/map.py", line 624, in match
    raise NotFound() from None
werkzeug.exceptions.NotFound: 404 Not Found: The requested URL was not found on the server. If you entered the URL manually please check your spelling and try again.

2025-04-21 21:24:09,506 - INFO - __main__ - Initializing ModelTrainer
2025-04-21 21:24:11,185 - INFO - __main__ - Features generated successfully for 16933 rows
2025-04-21 21:24:11,195 - INFO - __main__ - Preparing training data
2025-04-21 21:24:11,196 - INFO - __main__ - Total data size: 16933 rows
2025-04-21 21:24:11,198 - INFO - __main__ - Fitting scalers on the entire dataset
2025-04-21 21:24:11,201 - INFO - __main__ - Using features: ['open', 'high', 'low', 'close', 'volume', 'sma_5', 'sma_20', 'ema_5', 'ema_20', 'rsi', 'macd', 'macd_signal', 'bb_middle', 'bb_upper', 'bb_lower', 'price_change', 'price_change_5', 'volume_change', 'volume_ma_5']
2025-04-21 21:24:11,283 - INFO - __main__ - Using sequence_length=60, prediction_horizon=10
2025-04-21 21:24:24,580 - INFO - __main__ - Initial X shape: (4931, 60, 19), y shape: (4931, 10)
2025-04-21 21:24:24,586 - INFO - __main__ - Input shape: (60, 19)
2025-04-21 21:24:24,586 - INFO - __main__ - Initializing models with input shape: (60, 19)
2025-04-21 21:24:24,591 - INFO - __main__ - Models initialized successfully
2025-04-21 21:24:24,591 - INFO - __main__ - Using extended training configuration for model2: batch_size=64, epochs=default
2025-04-21 21:24:24,592 - INFO - __main__ - Model configured with batch_size=64
2025-04-21 21:24:24,686 - INFO - __main__ - Building and compiling model
2025-04-21 21:24:31,908 - INFO - __main__ - No GPUs found, using CPU
2025-04-21 21:24:31,909 - INFO - __main__ - Processing chunk 1/3: rows 0 to 5000
2025-04-21 21:24:31,910 - INFO - __main__ - Skipping first chunk as it was used for initialization
2025-04-21 21:24:31,911 - INFO - __main__ - Processing chunk 2/3: rows 4930 to 9930
2025-04-21 21:24:45,351 - INFO - __main__ - Chunk 2 data shapes - X_train: (3944, 60, 19), y_train: (3944, 10)
2025-04-21 21:24:45,352 - INFO - __main__ - Training on chunk 2
2025-04-21 21:24:45,353 - INFO - __main__ - Using 10 epochs for training on chunk 2
2025-04-21 21:32:02,440 - INFO - __main__ - Logging to file enabled
2025-04-21 21:32:11,313 - ERROR - __main__ - Unhandled exception: 404 Not Found: The requested URL was not found on the server. If you entered the URL manually please check your spelling and try again.
2025-04-21 21:32:11,367 - ERROR - __main__ - Traceback: Traceback (most recent call last):
  File "/home/olex/.local/lib/python3.8/site-packages/flask/app.py", line 1823, in full_dispatch_request
    rv = self.dispatch_request()
  File "/home/olex/.local/lib/python3.8/site-packages/flask/app.py", line 1788, in dispatch_request
    self.raise_routing_exception(req)
  File "/home/olex/.local/lib/python3.8/site-packages/flask/app.py", line 1770, in raise_routing_exception
    raise request.routing_exception  # type: ignore
  File "/home/olex/.local/lib/python3.8/site-packages/flask/ctx.py", line 351, in match_request
    result = self.url_adapter.match(return_rule=True)  # type: ignore
  File "/home/olex/.local/lib/python3.8/site-packages/werkzeug/routing/map.py", line 624, in match
    raise NotFound() from None
werkzeug.exceptions.NotFound: 404 Not Found: The requested URL was not found on the server. If you entered the URL manually please check your spelling and try again.

2025-04-21 21:32:14,214 - INFO - __main__ - Initializing ModelTrainer
2025-04-21 21:32:16,005 - INFO - __main__ - Features generated successfully for 18738 rows
2025-04-21 21:32:16,005 - INFO - __main__ - Preparing training data
2025-04-21 21:32:16,005 - INFO - __main__ - Total data size: 18738 rows
2025-04-21 21:32:16,006 - INFO - __main__ - Fitting scalers on the entire dataset
2025-04-21 21:32:16,014 - INFO - __main__ - Using features: ['open', 'high', 'low', 'close', 'volume', 'sma_5', 'sma_20', 'ema_5', 'ema_20', 'rsi', 'macd', 'macd_signal', 'bb_middle', 'bb_upper', 'bb_lower', 'price_change', 'price_change_5', 'volume_change', 'volume_ma_5']
2025-04-21 21:32:16,084 - INFO - __main__ - Using sequence_length=60, prediction_horizon=10
2025-04-21 21:32:24,206 - INFO - __main__ - Initial X shape: (2931, 60, 19), y shape: (2931, 10)
2025-04-21 21:32:24,229 - INFO - __main__ - Input shape: (60, 19)
2025-04-21 21:32:24,230 - INFO - __main__ - Initializing models with input shape: (60, 19)
2025-04-21 21:32:24,232 - ERROR - __main__ - Error during data preparation: 'ModelTrainer' object has no attribute 'enable_preloading'
2025-04-21 21:32:24,279 - ERROR - __main__ - Detailed traceback: Traceback (most recent call last):
  File "app.py", line 334, in start_training
    trainer.initialize_models(input_shape)
  File "/mnt/f/TheTurnAroundProject/training/trainer.py", line 48, in initialize_models
    if self.enable_preloading and self.check_models_exist():
AttributeError: 'ModelTrainer' object has no attribute 'enable_preloading'

2025-04-21 21:34:47,146 - INFO - __main__ - Logging to file enabled
2025-04-21 21:34:52,103 - ERROR - __main__ - Unhandled exception: 404 Not Found: The requested URL was not found on the server. If you entered the URL manually please check your spelling and try again.
2025-04-21 21:34:52,106 - ERROR - __main__ - Traceback: Traceback (most recent call last):
  File "/home/olex/.local/lib/python3.8/site-packages/flask/app.py", line 1823, in full_dispatch_request
    rv = self.dispatch_request()
  File "/home/olex/.local/lib/python3.8/site-packages/flask/app.py", line 1788, in dispatch_request
    self.raise_routing_exception(req)
  File "/home/olex/.local/lib/python3.8/site-packages/flask/app.py", line 1770, in raise_routing_exception
    raise request.routing_exception  # type: ignore
  File "/home/olex/.local/lib/python3.8/site-packages/flask/ctx.py", line 351, in match_request
    result = self.url_adapter.match(return_rule=True)  # type: ignore
  File "/home/olex/.local/lib/python3.8/site-packages/werkzeug/routing/map.py", line 624, in match
    raise NotFound() from None
werkzeug.exceptions.NotFound: 404 Not Found: The requested URL was not found on the server. If you entered the URL manually please check your spelling and try again.

2025-04-21 21:35:16,170 - ERROR - __main__ - Unhandled exception: 404 Not Found: The requested URL was not found on the server. If you entered the URL manually please check your spelling and try again.
2025-04-21 21:35:16,173 - ERROR - __main__ - Traceback: Traceback (most recent call last):
  File "/home/olex/.local/lib/python3.8/site-packages/flask/app.py", line 1823, in full_dispatch_request
    rv = self.dispatch_request()
  File "/home/olex/.local/lib/python3.8/site-packages/flask/app.py", line 1788, in dispatch_request
    self.raise_routing_exception(req)
  File "/home/olex/.local/lib/python3.8/site-packages/flask/app.py", line 1770, in raise_routing_exception
    raise request.routing_exception  # type: ignore
  File "/home/olex/.local/lib/python3.8/site-packages/flask/ctx.py", line 351, in match_request
    result = self.url_adapter.match(return_rule=True)  # type: ignore
  File "/home/olex/.local/lib/python3.8/site-packages/werkzeug/routing/map.py", line 624, in match
    raise NotFound() from None
werkzeug.exceptions.NotFound: 404 Not Found: The requested URL was not found on the server. If you entered the URL manually please check your spelling and try again.

2025-04-21 21:35:20,417 - INFO - __main__ - Initializing ModelTrainer
2025-04-21 21:35:22,190 - INFO - __main__ - Features generated successfully for 18738 rows
2025-04-21 21:35:22,201 - INFO - __main__ - Preparing training data
2025-04-21 21:35:22,203 - INFO - __main__ - Total data size: 18738 rows
2025-04-21 21:35:22,204 - INFO - __main__ - Fitting scalers on the entire dataset
2025-04-21 21:35:22,205 - INFO - __main__ - Using features: ['open', 'high', 'low', 'close', 'volume', 'sma_5', 'sma_20', 'ema_5', 'ema_20', 'rsi', 'macd', 'macd_signal', 'bb_middle', 'bb_upper', 'bb_lower', 'price_change', 'price_change_5', 'volume_change', 'volume_ma_5']
2025-04-21 21:35:22,259 - INFO - __main__ - Using sequence_length=60, prediction_horizon=10
2025-04-21 21:35:29,444 - INFO - __main__ - Initial X shape: (2931, 60, 19), y shape: (2931, 10)
2025-04-21 21:35:29,455 - INFO - __main__ - Input shape: (60, 19)
2025-04-21 21:35:29,458 - INFO - __main__ - Initializing models with input shape: (60, 19)
2025-04-21 21:35:29,467 - ERROR - __main__ - Error during data preparation: No module named 'models.model1_bayesian'
2025-04-21 21:35:29,493 - ERROR - __main__ - Detailed traceback: Traceback (most recent call last):
  File "app.py", line 334, in start_training
    trainer.initialize_models(input_shape)
  File "/mnt/f/TheTurnAroundProject/training/trainer.py", line 70, in initialize_models
    from models.model1_bayesian import BayesianNeuralNetwork
ModuleNotFoundError: No module named 'models.model1_bayesian'

2025-04-21 21:39:14,556 - INFO - __main__ - Logging to file enabled
2025-04-21 21:39:20,648 - ERROR - __main__ - Unhandled exception: 404 Not Found: The requested URL was not found on the server. If you entered the URL manually please check your spelling and try again.
2025-04-21 21:39:20,651 - ERROR - __main__ - Traceback: Traceback (most recent call last):
  File "/home/olex/.local/lib/python3.8/site-packages/flask/app.py", line 1823, in full_dispatch_request
    rv = self.dispatch_request()
  File "/home/olex/.local/lib/python3.8/site-packages/flask/app.py", line 1788, in dispatch_request
    self.raise_routing_exception(req)
  File "/home/olex/.local/lib/python3.8/site-packages/flask/app.py", line 1770, in raise_routing_exception
    raise request.routing_exception  # type: ignore
  File "/home/olex/.local/lib/python3.8/site-packages/flask/ctx.py", line 351, in match_request
    result = self.url_adapter.match(return_rule=True)  # type: ignore
  File "/home/olex/.local/lib/python3.8/site-packages/werkzeug/routing/map.py", line 624, in match
    raise NotFound() from None
werkzeug.exceptions.NotFound: 404 Not Found: The requested URL was not found on the server. If you entered the URL manually please check your spelling and try again.

2025-04-21 21:39:26,769 - ERROR - __main__ - Unhandled exception: 404 Not Found: The requested URL was not found on the server. If you entered the URL manually please check your spelling and try again.
2025-04-21 21:39:26,775 - ERROR - __main__ - Traceback: Traceback (most recent call last):
  File "/home/olex/.local/lib/python3.8/site-packages/flask/app.py", line 1823, in full_dispatch_request
    rv = self.dispatch_request()
  File "/home/olex/.local/lib/python3.8/site-packages/flask/app.py", line 1788, in dispatch_request
    self.raise_routing_exception(req)
  File "/home/olex/.local/lib/python3.8/site-packages/flask/app.py", line 1770, in raise_routing_exception
    raise request.routing_exception  # type: ignore
  File "/home/olex/.local/lib/python3.8/site-packages/flask/ctx.py", line 351, in match_request
    result = self.url_adapter.match(return_rule=True)  # type: ignore
  File "/home/olex/.local/lib/python3.8/site-packages/werkzeug/routing/map.py", line 624, in match
    raise NotFound() from None
werkzeug.exceptions.NotFound: 404 Not Found: The requested URL was not found on the server. If you entered the URL manually please check your spelling and try again.

2025-04-21 21:39:31,745 - INFO - __main__ - Initializing ModelTrainer
2025-04-21 21:39:33,453 - INFO - __main__ - Features generated successfully for 17961 rows
2025-04-21 21:39:33,456 - INFO - __main__ - Preparing training data
2025-04-21 21:39:33,461 - INFO - __main__ - Total data size: 17961 rows
2025-04-21 21:39:33,463 - INFO - __main__ - Fitting scalers on the entire dataset
2025-04-21 21:39:33,465 - INFO - __main__ - Using features: ['open', 'high', 'low', 'close', 'volume', 'sma_5', 'sma_20', 'ema_5', 'ema_20', 'rsi', 'macd', 'macd_signal', 'bb_middle', 'bb_upper', 'bb_lower', 'price_change', 'price_change_5', 'volume_change', 'volume_ma_5']
2025-04-21 21:39:33,514 - INFO - __main__ - Using sequence_length=60, prediction_horizon=10
2025-04-21 21:39:40,230 - INFO - __main__ - Initial X shape: (2931, 60, 19), y shape: (2931, 10)
2025-04-21 21:39:40,235 - INFO - __main__ - Input shape: (60, 19)
2025-04-21 21:39:40,236 - INFO - __main__ - Initializing models with input shape: (60, 19)
2025-04-21 21:39:40,337 - INFO - __main__ - Models initialized successfully
2025-04-21 21:39:40,338 - INFO - __main__ - Selected model: model2
2025-04-21 21:39:40,338 - INFO - __main__ - Using extended training configuration for model2: batch_size=64, epochs=default
2025-04-21 21:39:40,339 - INFO - __main__ - Model configured with batch_size=64
2025-04-21 21:39:40,357 - INFO - __main__ - Building and compiling model
2025-04-21 21:39:48,273 - INFO - __main__ - No GPUs found, using CPU
2025-04-21 21:39:48,277 - INFO - __main__ - Preparing to train on 7 chunks with dataset size: 17961 rows
2025-04-21 21:39:48,280 - INFO - __main__ - Processing chunk 1/7: rows 0 to 3000
2025-04-21 21:39:48,288 - INFO - __main__ - Chunk 1 size: 3000 rows
2025-04-21 21:39:48,290 - INFO - __main__ - Skipping first chunk as it was used for initialization
2025-04-21 21:39:48,292 - INFO - __main__ - Processing chunk 2/7: rows 2930 to 5930
2025-04-21 21:39:48,296 - INFO - __main__ - Chunk 2 size: 3000 rows
2025-04-21 21:39:57,420 - INFO - __main__ - Created 2931 sequences from chunk 2
2025-04-21 21:39:57,451 - INFO - __main__ - Chunk 2 data shapes - X_train: (2344, 60, 19), y_train: (2344, 10)
2025-04-21 21:39:57,452 - INFO - __main__ - Training on chunk 2
2025-04-21 21:39:57,454 - INFO - __main__ - Using 10 epochs for training on chunk 2
2025-04-21 21:42:40,638 - INFO - __main__ - Logging to file enabled
2025-04-21 21:42:49,543 - ERROR - __main__ - Unhandled exception: 404 Not Found: The requested URL was not found on the server. If you entered the URL manually please check your spelling and try again.
2025-04-21 21:42:49,776 - ERROR - __main__ - Traceback: Traceback (most recent call last):
  File "/home/olex/.local/lib/python3.8/site-packages/flask/app.py", line 1823, in full_dispatch_request
    rv = self.dispatch_request()
  File "/home/olex/.local/lib/python3.8/site-packages/flask/app.py", line 1788, in dispatch_request
    self.raise_routing_exception(req)
  File "/home/olex/.local/lib/python3.8/site-packages/flask/app.py", line 1770, in raise_routing_exception
    raise request.routing_exception  # type: ignore
  File "/home/olex/.local/lib/python3.8/site-packages/flask/ctx.py", line 351, in match_request
    result = self.url_adapter.match(return_rule=True)  # type: ignore
  File "/home/olex/.local/lib/python3.8/site-packages/werkzeug/routing/map.py", line 624, in match
    raise NotFound() from None
werkzeug.exceptions.NotFound: 404 Not Found: The requested URL was not found on the server. If you entered the URL manually please check your spelling and try again.

2025-04-21 21:42:52,312 - INFO - __main__ - Initializing ModelTrainer
2025-04-21 21:42:53,941 - INFO - __main__ - Features generated successfully for 18738 rows
2025-04-21 21:42:53,942 - INFO - __main__ - Preparing training data
2025-04-21 21:42:53,946 - INFO - __main__ - Total data size: 18738 rows
2025-04-21 21:42:53,947 - INFO - __main__ - Fitting scalers on the entire dataset
2025-04-21 21:42:53,950 - INFO - __main__ - Using features: ['open', 'high', 'low', 'close', 'volume', 'sma_5', 'sma_20', 'ema_5', 'ema_20', 'rsi', 'macd', 'macd_signal', 'bb_middle', 'bb_upper', 'bb_lower', 'price_change', 'price_change_5', 'volume_change', 'volume_ma_5']
2025-04-21 21:42:53,996 - INFO - __main__ - Using sequence_length=60, prediction_horizon=10
2025-04-21 21:43:02,274 - INFO - __main__ - Initial X shape: (2931, 60, 19), y shape: (2931, 10)
2025-04-21 21:43:02,281 - INFO - __main__ - Input shape: (60, 19)
2025-04-21 21:43:02,282 - INFO - __main__ - Initializing models with input shape: (60, 19)
2025-04-21 21:43:02,357 - INFO - __main__ - Models initialized successfully
2025-04-21 21:43:02,362 - INFO - __main__ - Selected model: model2
2025-04-21 21:43:02,363 - INFO - __main__ - Using extended training configuration for model2: batch_size=64, epochs=default
2025-04-21 21:43:02,364 - INFO - __main__ - Model configured with batch_size=64
2025-04-21 21:43:02,382 - INFO - __main__ - Building and compiling model
2025-04-21 21:43:07,108 - INFO - __main__ - No GPUs found, using CPU
2025-04-21 21:43:07,109 - INFO - __main__ - Preparing to train on 7 chunks with dataset size: 18738 rows
2025-04-21 21:43:07,112 - INFO - __main__ - Chunk size: 3000, Overlap: 70, Effective chunk size: 2930
2025-04-21 21:43:07,113 - INFO - __main__ - Processing chunk 1/7: rows 0 to 3000
2025-04-21 21:43:07,113 - INFO - __main__ - Chunk 1 size: 3000 rows
2025-04-21 21:43:07,114 - INFO - __main__ - Skipping first chunk as it was used for initialization
2025-04-21 21:43:07,115 - INFO - __main__ - Processing chunk 2/7: rows 2930 to 5930
2025-04-21 21:43:07,116 - INFO - __main__ - Chunk 2 size: 3000 rows
2025-04-21 21:43:15,406 - INFO - __main__ - Created 2931 sequences from chunk 2
2025-04-21 21:43:15,443 - INFO - __main__ - Chunk 2 data shapes - X_train: (2344, 60, 19), y_train: (2344, 10)
2025-04-21 21:43:15,444 - INFO - __main__ - Training on chunk 2
2025-04-21 21:43:15,446 - INFO - __main__ - Using 10 epochs for training on chunk 2
2025-04-21 21:48:53,883 - INFO - __main__ - Logging to file enabled
2025-04-21 21:49:04,729 - ERROR - __main__ - Unhandled exception: 404 Not Found: The requested URL was not found on the server. If you entered the URL manually please check your spelling and try again.
2025-04-21 21:49:04,754 - ERROR - __main__ - Traceback: Traceback (most recent call last):
  File "/home/olex/.local/lib/python3.8/site-packages/flask/app.py", line 1823, in full_dispatch_request
    rv = self.dispatch_request()
  File "/home/olex/.local/lib/python3.8/site-packages/flask/app.py", line 1788, in dispatch_request
    self.raise_routing_exception(req)
  File "/home/olex/.local/lib/python3.8/site-packages/flask/app.py", line 1770, in raise_routing_exception
    raise request.routing_exception  # type: ignore
  File "/home/olex/.local/lib/python3.8/site-packages/flask/ctx.py", line 351, in match_request
    result = self.url_adapter.match(return_rule=True)  # type: ignore
  File "/home/olex/.local/lib/python3.8/site-packages/werkzeug/routing/map.py", line 624, in match
    raise NotFound() from None
werkzeug.exceptions.NotFound: 404 Not Found: The requested URL was not found on the server. If you entered the URL manually please check your spelling and try again.

2025-04-21 21:49:08,374 - INFO - __main__ - Initializing ModelTrainer
2025-04-21 21:49:10,035 - INFO - __main__ - Features generated successfully for 17961 rows
2025-04-21 21:49:10,035 - INFO - __main__ - Preparing training data
2025-04-21 21:49:10,036 - INFO - __main__ - Total data size: 17961 rows
2025-04-21 21:49:10,037 - INFO - __main__ - Fitting scalers on the entire dataset
2025-04-21 21:49:10,038 - INFO - __main__ - Using features: ['open', 'high', 'low', 'close', 'volume', 'sma_5', 'sma_20', 'ema_5', 'ema_20', 'rsi', 'macd', 'macd_signal', 'bb_middle', 'bb_upper', 'bb_lower', 'price_change', 'price_change_5', 'volume_change', 'volume_ma_5']
2025-04-21 21:49:10,122 - INFO - __main__ - Using sequence_length=60, prediction_horizon=10
2025-04-21 21:49:18,191 - INFO - __main__ - Initial X shape: (2931, 60, 19), y shape: (2931, 10)
2025-04-21 21:49:18,197 - INFO - __main__ - Input shape: (60, 19)
2025-04-21 21:49:18,199 - INFO - __main__ - Initializing models with input shape: (60, 19)
2025-04-21 21:49:18,215 - INFO - __main__ - Models initialized successfully
2025-04-21 21:49:18,216 - INFO - __main__ - Selected model: model2
2025-04-21 21:49:18,219 - INFO - __main__ - Using extended training configuration for model2: batch_size=64, epochs=default
2025-04-21 21:49:18,220 - INFO - __main__ - Model configured with batch_size=64
2025-04-21 21:49:18,240 - INFO - __main__ - Building and compiling model
2025-04-21 21:49:23,813 - INFO - __main__ - No GPUs found, using CPU
2025-04-21 21:49:23,815 - INFO - __main__ - Preparing to train on 7 chunks with dataset size: 17961 rows
2025-04-21 21:49:23,822 - INFO - __main__ - Chunk size: 3000, Overlap: 70, Effective chunk size: 2930
2025-04-21 21:49:23,823 - INFO - __main__ - Processing chunk 1/7: rows 0 to 3000
2025-04-21 21:49:23,824 - INFO - __main__ - Chunk 1 size: 3000 rows
2025-04-21 21:49:23,825 - INFO - __main__ - Skipping first chunk as it was used for initialization
2025-04-21 21:49:23,825 - INFO - __main__ - Processing chunk 2/7: rows 2930 to 5930
2025-04-21 21:49:23,830 - INFO - __main__ - Chunk 2 size: 3000 rows
2025-04-21 21:49:31,791 - INFO - __main__ - Created 2931 sequences from chunk 2
2025-04-21 21:49:31,818 - INFO - __main__ - Chunk 2 data shapes - X_train: (2344, 60, 19), y_train: (2344, 10)
2025-04-21 21:49:31,819 - INFO - __main__ - Training on chunk 2
2025-04-21 21:49:31,820 - INFO - __main__ - Using 10 epochs for training on chunk 2
2025-04-21 21:49:52,009 - ERROR - __main__ - Error getting models: __init__() missing 1 required positional argument: 'input_shape'
2025-04-21 21:50:00,215 - ERROR - __main__ - Error during data preparation: 'epoch'
2025-04-21 21:50:00,220 - ERROR - __main__ - Detailed traceback: Traceback (most recent call last):
  File "app.py", line 478, in start_training
    history = model.model.fit(
  File "/home/olex/.local/lib/python3.8/site-packages/keras/utils/traceback_utils.py", line 67, in error_handler
    raise e.with_traceback(filtered_tb) from None
  File "app.py", line 476, in on_batch_end
    training_status["status_message"] = f"Training chunk {chunk_idx+1}/{num_chunks} - Epoch {self.params['epoch']+1}/{chunk_epochs} - Batch {batch}/{total_batches}"
KeyError: 'epoch'

2025-04-21 21:51:05,082 - INFO - __main__ - Logging to file enabled
2025-04-21 21:51:11,398 - ERROR - __main__ - Unhandled exception: 404 Not Found: The requested URL was not found on the server. If you entered the URL manually please check your spelling and try again.
2025-04-21 21:51:11,401 - ERROR - __main__ - Traceback: Traceback (most recent call last):
  File "/home/olex/.local/lib/python3.8/site-packages/flask/app.py", line 1823, in full_dispatch_request
    rv = self.dispatch_request()
  File "/home/olex/.local/lib/python3.8/site-packages/flask/app.py", line 1788, in dispatch_request
    self.raise_routing_exception(req)
  File "/home/olex/.local/lib/python3.8/site-packages/flask/app.py", line 1770, in raise_routing_exception
    raise request.routing_exception  # type: ignore
  File "/home/olex/.local/lib/python3.8/site-packages/flask/ctx.py", line 351, in match_request
    result = self.url_adapter.match(return_rule=True)  # type: ignore
  File "/home/olex/.local/lib/python3.8/site-packages/werkzeug/routing/map.py", line 624, in match
    raise NotFound() from None
werkzeug.exceptions.NotFound: 404 Not Found: The requested URL was not found on the server. If you entered the URL manually please check your spelling and try again.

2025-04-21 21:51:13,552 - ERROR - __main__ - Unhandled exception: 404 Not Found: The requested URL was not found on the server. If you entered the URL manually please check your spelling and try again.
2025-04-21 21:51:13,554 - ERROR - __main__ - Traceback: Traceback (most recent call last):
  File "/home/olex/.local/lib/python3.8/site-packages/flask/app.py", line 1823, in full_dispatch_request
    rv = self.dispatch_request()
  File "/home/olex/.local/lib/python3.8/site-packages/flask/app.py", line 1788, in dispatch_request
    self.raise_routing_exception(req)
  File "/home/olex/.local/lib/python3.8/site-packages/flask/app.py", line 1770, in raise_routing_exception
    raise request.routing_exception  # type: ignore
  File "/home/olex/.local/lib/python3.8/site-packages/flask/ctx.py", line 351, in match_request
    result = self.url_adapter.match(return_rule=True)  # type: ignore
  File "/home/olex/.local/lib/python3.8/site-packages/werkzeug/routing/map.py", line 624, in match
    raise NotFound() from None
werkzeug.exceptions.NotFound: 404 Not Found: The requested URL was not found on the server. If you entered the URL manually please check your spelling and try again.

2025-04-21 21:51:15,841 - INFO - __main__ - Initializing ModelTrainer
2025-04-21 21:51:17,756 - INFO - __main__ - Features generated successfully for 17961 rows
2025-04-21 21:51:17,759 - INFO - __main__ - Preparing training data
2025-04-21 21:51:17,760 - INFO - __main__ - Total data size: 17961 rows
2025-04-21 21:51:17,763 - INFO - __main__ - Fitting scalers on the entire dataset
2025-04-21 21:51:17,765 - INFO - __main__ - Using features: ['open', 'high', 'low', 'close', 'volume', 'sma_5', 'sma_20', 'ema_5', 'ema_20', 'rsi', 'macd', 'macd_signal', 'bb_middle', 'bb_upper', 'bb_lower', 'price_change', 'price_change_5', 'volume_change', 'volume_ma_5']
2025-04-21 21:51:17,813 - INFO - __main__ - Using sequence_length=60, prediction_horizon=10
2025-04-21 21:51:26,426 - INFO - __main__ - Initial X shape: (2931, 60, 19), y shape: (2931, 10)
2025-04-21 21:51:26,433 - INFO - __main__ - Input shape: (60, 19)
2025-04-21 21:51:26,434 - INFO - __main__ - Initializing models with input shape: (60, 19)
2025-04-21 21:51:26,456 - INFO - __main__ - Models initialized successfully
2025-04-21 21:51:26,461 - INFO - __main__ - Selected model: model2
2025-04-21 21:51:26,467 - INFO - __main__ - Using extended training configuration for model2: batch_size=64, epochs=default
2025-04-21 21:51:26,469 - INFO - __main__ - Model configured with batch_size=64
2025-04-21 21:51:26,488 - INFO - __main__ - Building and compiling model
2025-04-21 21:51:31,300 - INFO - __main__ - No GPUs found, using CPU
2025-04-21 21:51:31,301 - INFO - __main__ - Preparing to train on 7 chunks with dataset size: 17961 rows
2025-04-21 21:51:31,301 - INFO - __main__ - Chunk size: 3000, Overlap: 70, Effective chunk size: 2930
2025-04-21 21:51:31,302 - INFO - __main__ - Processing chunk 1/7: rows 0 to 3000
2025-04-21 21:51:31,302 - INFO - __main__ - Chunk 1 size: 3000 rows
2025-04-21 21:51:31,303 - INFO - __main__ - Skipping first chunk as it was used for initialization
2025-04-21 21:51:31,303 - INFO - __main__ - Processing chunk 2/7: rows 2930 to 5930
2025-04-21 21:51:31,303 - INFO - __main__ - Chunk 2 size: 3000 rows
2025-04-21 21:51:39,895 - INFO - __main__ - Created 2931 sequences from chunk 2
2025-04-21 21:51:39,917 - INFO - __main__ - Chunk 2 data shapes - X_train: (2344, 60, 19), y_train: (2344, 10)
2025-04-21 21:51:39,921 - INFO - __main__ - Training on chunk 2
2025-04-21 21:51:39,923 - INFO - __main__ - Using 10 epochs for training on chunk 2
2025-04-21 21:52:07,110 - ERROR - __main__ - Error getting models: __init__() missing 1 required positional argument: 'input_shape'
2025-04-21 21:55:04,977 - INFO - __main__ - Logging to file enabled
2025-04-21 21:55:10,547 - ERROR - __main__ - Unhandled exception: 404 Not Found: The requested URL was not found on the server. If you entered the URL manually please check your spelling and try again.
2025-04-21 21:55:10,549 - ERROR - __main__ - Traceback: Traceback (most recent call last):
  File "/home/olex/.local/lib/python3.8/site-packages/flask/app.py", line 1823, in full_dispatch_request
    rv = self.dispatch_request()
  File "/home/olex/.local/lib/python3.8/site-packages/flask/app.py", line 1788, in dispatch_request
    self.raise_routing_exception(req)
  File "/home/olex/.local/lib/python3.8/site-packages/flask/app.py", line 1770, in raise_routing_exception
    raise request.routing_exception  # type: ignore
  File "/home/olex/.local/lib/python3.8/site-packages/flask/ctx.py", line 351, in match_request
    result = self.url_adapter.match(return_rule=True)  # type: ignore
  File "/home/olex/.local/lib/python3.8/site-packages/werkzeug/routing/map.py", line 624, in match
    raise NotFound() from None
werkzeug.exceptions.NotFound: 404 Not Found: The requested URL was not found on the server. If you entered the URL manually please check your spelling and try again.

2025-04-21 21:55:12,199 - ERROR - __main__ - Unhandled exception: 404 Not Found: The requested URL was not found on the server. If you entered the URL manually please check your spelling and try again.
2025-04-21 21:55:12,204 - ERROR - __main__ - Traceback: Traceback (most recent call last):
  File "/home/olex/.local/lib/python3.8/site-packages/flask/app.py", line 1823, in full_dispatch_request
    rv = self.dispatch_request()
  File "/home/olex/.local/lib/python3.8/site-packages/flask/app.py", line 1788, in dispatch_request
    self.raise_routing_exception(req)
  File "/home/olex/.local/lib/python3.8/site-packages/flask/app.py", line 1770, in raise_routing_exception
    raise request.routing_exception  # type: ignore
  File "/home/olex/.local/lib/python3.8/site-packages/flask/ctx.py", line 351, in match_request
    result = self.url_adapter.match(return_rule=True)  # type: ignore
  File "/home/olex/.local/lib/python3.8/site-packages/werkzeug/routing/map.py", line 624, in match
    raise NotFound() from None
werkzeug.exceptions.NotFound: 404 Not Found: The requested URL was not found on the server. If you entered the URL manually please check your spelling and try again.

2025-04-21 21:55:14,184 - INFO - __main__ - Initializing ModelTrainer
2025-04-21 21:55:15,690 - INFO - __main__ - Features generated successfully for 15344 rows
2025-04-21 21:55:15,695 - INFO - __main__ - Preparing training data
2025-04-21 21:55:15,696 - INFO - __main__ - Total data size: 15344 rows
2025-04-21 21:55:15,705 - INFO - __main__ - Fitting scalers on the entire dataset
2025-04-21 21:55:15,707 - INFO - __main__ - Using features: ['open', 'high', 'low', 'close', 'volume', 'sma_5', 'sma_20', 'ema_5', 'ema_20', 'rsi', 'macd', 'macd_signal', 'bb_middle', 'bb_upper', 'bb_lower', 'price_change', 'price_change_5', 'volume_change', 'volume_ma_5']
2025-04-21 21:55:15,755 - INFO - __main__ - Using sequence_length=60, prediction_horizon=10
2025-04-21 21:55:24,638 - INFO - __main__ - Initial X shape: (2931, 60, 19), y shape: (2931, 10)
2025-04-21 21:55:24,647 - INFO - __main__ - Input shape: (60, 19)
2025-04-21 21:55:24,648 - INFO - __main__ - Initializing models with input shape: (60, 19)
2025-04-21 21:55:24,664 - INFO - __main__ - Models initialized successfully
2025-04-21 21:55:24,664 - INFO - __main__ - Selected model: model1
2025-04-21 21:55:24,665 - INFO - __main__ - Model configured with batch_size=32
2025-04-21 21:55:24,684 - INFO - __main__ - Building and compiling model
2025-04-21 21:55:27,153 - INFO - __main__ - No GPUs found, using CPU
2025-04-21 21:55:27,154 - INFO - __main__ - Preparing to train on 6 chunks with dataset size: 15344 rows
2025-04-21 21:55:27,155 - INFO - __main__ - Chunk size: 3000, Overlap: 70, Effective chunk size: 2930
2025-04-21 21:55:27,155 - INFO - __main__ - Processing chunk 1/6: rows 0 to 3000
2025-04-21 21:55:27,156 - INFO - __main__ - Chunk 1 size: 3000 rows
2025-04-21 21:55:27,156 - INFO - __main__ - Skipping first chunk as it was used for initialization
2025-04-21 21:55:27,157 - INFO - __main__ - Processing chunk 2/6: rows 2930 to 5930
2025-04-21 21:55:27,158 - INFO - __main__ - Chunk 2 size: 3000 rows
2025-04-21 21:55:35,019 - INFO - __main__ - Created 2931 sequences from chunk 2
2025-04-21 21:55:35,049 - INFO - __main__ - Chunk 2 data shapes - X_train: (2344, 60, 19), y_train: (2344, 10)
2025-04-21 21:55:35,059 - INFO - __main__ - Training on chunk 2
2025-04-21 21:55:35,061 - INFO - __main__ - Using 2 epochs for training on chunk 2
2025-04-21 21:55:55,166 - ERROR - __main__ - Error getting models: __init__() missing 1 required positional argument: 'input_shape'
2025-04-21 21:57:24,240 - INFO - __main__ - Chunk 2 validation - Loss: 0.016795430332422256, MAE: 0.08947394043207169
2025-04-21 21:57:24,916 - INFO - __main__ - Processing chunk 3/6: rows 5860 to 8860
2025-04-21 21:57:24,917 - INFO - __main__ - Chunk 3 size: 3000 rows
2025-04-21 21:57:29,677 - INFO - __main__ - Created 2931 sequences from chunk 3
2025-04-21 21:57:29,691 - INFO - __main__ - Chunk 3 data shapes - X_train: (2344, 60, 19), y_train: (2344, 10)
2025-04-21 21:57:29,692 - INFO - __main__ - Training on chunk 3
2025-04-21 21:57:29,692 - INFO - __main__ - Using 2 epochs for training on chunk 3
2025-04-21 21:59:01,847 - INFO - __main__ - Chunk 3 validation - Loss: 0.025056179612874985, MAE: 0.12248080223798752
2025-04-21 21:59:01,998 - INFO - __main__ - Processing chunk 4/6: rows 8790 to 11790
2025-04-21 21:59:02,000 - INFO - __main__ - Chunk 4 size: 3000 rows
2025-04-21 21:59:06,770 - INFO - __main__ - Created 2931 sequences from chunk 4
2025-04-21 21:59:06,784 - INFO - __main__ - Chunk 4 data shapes - X_train: (2344, 60, 19), y_train: (2344, 10)
2025-04-21 21:59:06,785 - INFO - __main__ - Training on chunk 4
2025-04-21 21:59:06,785 - INFO - __main__ - Using 2 epochs for training on chunk 4
2025-04-21 22:00:39,180 - INFO - __main__ - Chunk 4 validation - Loss: 0.021026507019996643, MAE: 0.11528180539608002
2025-04-21 22:00:39,334 - INFO - __main__ - Processing chunk 5/6: rows 11720 to 14720
2025-04-21 22:00:39,335 - INFO - __main__ - Chunk 5 size: 3000 rows
2025-04-21 22:00:44,065 - INFO - __main__ - Created 2931 sequences from chunk 5
2025-04-21 22:00:44,085 - INFO - __main__ - Chunk 5 data shapes - X_train: (2344, 60, 19), y_train: (2344, 10)
2025-04-21 22:00:44,085 - INFO - __main__ - Training on chunk 5
2025-04-21 22:00:44,086 - INFO - __main__ - Using 2 epochs for training on chunk 5
2025-04-21 22:02:16,594 - INFO - __main__ - Chunk 5 validation - Loss: 0.019791482016444206, MAE: 0.11261153966188431
2025-04-21 22:02:16,748 - INFO - __main__ - Processing chunk 6/6: rows 14650 to 15344
2025-04-21 22:02:16,749 - INFO - __main__ - Chunk 6 size: 694 rows
2025-04-21 22:02:17,775 - INFO - __main__ - Created 625 sequences from chunk 6
2025-04-21 22:02:17,779 - INFO - __main__ - Chunk 6 data shapes - X_train: (500, 60, 19), y_train: (500, 10)
2025-04-21 22:02:17,780 - INFO - __main__ - Training on chunk 6
2025-04-21 22:02:17,780 - INFO - __main__ - Using 2 epochs for training on chunk 6
2025-04-21 22:02:37,847 - INFO - __main__ - Chunk 6 validation - Loss: 0.02069677785038948, MAE: 0.11399687081575394
2025-04-21 22:02:42,669 - INFO - __main__ - Final evaluation - Loss: 0.034920584410429, MAE: 0.17720229923725128
2025-04-21 22:03:14,482 - ERROR - __main__ - Error getting models: __init__() missing 1 required positional argument: 'input_shape'
2025-04-21 22:16:04,376 - INFO - __main__ - Logging to file enabled
2025-04-23 11:55:10,220 - INFO - __main__ - Logging to file enabled
2025-04-23 11:56:01,751 - ERROR - __main__ - Unhandled exception: 404 Not Found: The requested URL was not found on the server. If you entered the URL manually please check your spelling and try again.
2025-04-23 11:56:01,764 - ERROR - __main__ - Traceback: Traceback (most recent call last):
  File "/home/olex/.local/lib/python3.8/site-packages/flask/app.py", line 1823, in full_dispatch_request
    rv = self.dispatch_request()
  File "/home/olex/.local/lib/python3.8/site-packages/flask/app.py", line 1788, in dispatch_request
    self.raise_routing_exception(req)
  File "/home/olex/.local/lib/python3.8/site-packages/flask/app.py", line 1770, in raise_routing_exception
    raise request.routing_exception  # type: ignore
  File "/home/olex/.local/lib/python3.8/site-packages/flask/ctx.py", line 351, in match_request
    result = self.url_adapter.match(return_rule=True)  # type: ignore
  File "/home/olex/.local/lib/python3.8/site-packages/werkzeug/routing/map.py", line 624, in match
    raise NotFound() from None
werkzeug.exceptions.NotFound: 404 Not Found: The requested URL was not found on the server. If you entered the URL manually please check your spelling and try again.

2025-04-23 11:56:14,259 - INFO - __main__ - Initializing ModelTrainer
2025-04-23 11:56:16,147 - INFO - __main__ - Features generated successfully for 18738 rows
2025-04-23 11:56:16,148 - INFO - __main__ - Preparing training data
2025-04-23 11:56:16,149 - INFO - __main__ - Total data size: 18738 rows
2025-04-23 11:56:16,149 - INFO - __main__ - Fitting scalers on the entire dataset
2025-04-23 11:56:16,151 - INFO - __main__ - Using features: ['open', 'high', 'low', 'close', 'volume', 'sma_5', 'sma_20', 'ema_5', 'ema_20', 'rsi', 'macd', 'macd_signal', 'bb_middle', 'bb_upper', 'bb_lower', 'price_change', 'price_change_5', 'volume_change', 'volume_ma_5']
2025-04-23 11:56:16,190 - INFO - __main__ - Using sequence_length=60, prediction_horizon=10
2025-04-23 11:56:26,977 - INFO - __main__ - Initial X shape: (2931, 60, 19), y shape: (2931, 10)
2025-04-23 11:56:26,983 - INFO - __main__ - Input shape: (60, 19)
2025-04-23 11:56:26,985 - INFO - __main__ - Initializing models with input shape: (60, 19)
2025-04-23 11:56:27,025 - INFO - __main__ - Models initialized successfully
2025-04-23 11:56:27,028 - INFO - __main__ - Selected model: model1
2025-04-23 11:56:27,031 - INFO - __main__ - Model configured with batch_size=32
2025-04-23 11:56:27,061 - INFO - __main__ - Building and compiling model
2025-04-23 11:56:30,180 - INFO - __main__ - No GPUs found, using CPU
2025-04-23 11:56:30,183 - INFO - __main__ - Preparing to train on 7 chunks with dataset size: 18738 rows
2025-04-23 11:56:30,189 - INFO - __main__ - Chunk size: 3000, Overlap: 70, Effective chunk size: 2930
2025-04-23 11:56:30,228 - INFO - __main__ - Processing chunk 1/7: rows 0 to 3000
2025-04-23 11:56:30,230 - INFO - __main__ - Chunk 1 size: 3000 rows
2025-04-23 11:56:30,230 - INFO - __main__ - Skipping first chunk as it was used for initialization
2025-04-23 11:56:30,231 - INFO - __main__ - Processing chunk 2/7: rows 2930 to 5930
2025-04-23 11:56:30,232 - INFO - __main__ - Chunk 2 size: 3000 rows
2025-04-23 11:56:39,645 - INFO - __main__ - Created 2931 sequences from chunk 2
2025-04-23 11:56:39,685 - INFO - __main__ - Chunk 2 data shapes - X_train: (2344, 60, 19), y_train: (2344, 10)
2025-04-23 11:56:39,686 - INFO - __main__ - Training on chunk 2
2025-04-23 11:56:39,687 - INFO - __main__ - Using 2 epochs for training on chunk 2
2025-04-23 11:56:57,891 - ERROR - __main__ - Error getting models: 'NoneType' object has no attribute 'get'
2025-04-23 11:58:40,115 - INFO - __main__ - Chunk 2 validation - Loss: 0.05338803306221962, MAE: 0.18000705540180206
2025-04-23 11:58:40,829 - INFO - __main__ - Processing chunk 3/7: rows 5860 to 8860
2025-04-23 11:58:40,830 - INFO - __main__ - Chunk 3 size: 3000 rows
2025-04-23 11:58:46,010 - INFO - __main__ - Created 2931 sequences from chunk 3
2025-04-23 11:58:46,028 - INFO - __main__ - Chunk 3 data shapes - X_train: (2344, 60, 19), y_train: (2344, 10)
2025-04-23 11:58:46,028 - INFO - __main__ - Training on chunk 3
2025-04-23 11:58:46,029 - INFO - __main__ - Using 2 epochs for training on chunk 3
2025-04-23 12:00:23,489 - INFO - __main__ - Chunk 3 validation - Loss: 0.022981815040111542, MAE: 0.11846241354942322
2025-04-23 12:00:23,636 - INFO - __main__ - Processing chunk 4/7: rows 8790 to 11790
2025-04-23 12:00:23,637 - INFO - __main__ - Chunk 4 size: 3000 rows
2025-04-23 12:00:28,863 - INFO - __main__ - Created 2931 sequences from chunk 4
2025-04-23 12:00:28,878 - INFO - __main__ - Chunk 4 data shapes - X_train: (2344, 60, 19), y_train: (2344, 10)
2025-04-23 12:00:28,879 - INFO - __main__ - Training on chunk 4
2025-04-23 12:00:28,879 - INFO - __main__ - Using 2 epochs for training on chunk 4
2025-04-23 12:02:08,225 - INFO - __main__ - Chunk 4 validation - Loss: 0.004270085599273443, MAE: 0.046326447278261185
2025-04-23 12:02:08,373 - INFO - __main__ - Processing chunk 5/7: rows 11720 to 14720
2025-04-23 12:02:08,374 - INFO - __main__ - Chunk 5 size: 3000 rows
2025-04-23 12:02:13,517 - INFO - __main__ - Created 2931 sequences from chunk 5
2025-04-23 12:02:13,532 - INFO - __main__ - Chunk 5 data shapes - X_train: (2344, 60, 19), y_train: (2344, 10)
2025-04-23 12:02:13,533 - INFO - __main__ - Training on chunk 5
2025-04-23 12:02:13,533 - INFO - __main__ - Using 2 epochs for training on chunk 5
2025-04-23 12:03:50,516 - INFO - __main__ - Chunk 5 validation - Loss: 0.005445360206067562, MAE: 0.053964320570230484
2025-04-23 12:03:50,662 - INFO - __main__ - Processing chunk 6/7: rows 14650 to 17650
2025-04-23 12:03:50,663 - INFO - __main__ - Chunk 6 size: 3000 rows
2025-04-23 12:03:55,662 - INFO - __main__ - Created 2931 sequences from chunk 6
2025-04-23 12:03:55,675 - INFO - __main__ - Chunk 6 data shapes - X_train: (2344, 60, 19), y_train: (2344, 10)
2025-04-23 12:03:55,676 - INFO - __main__ - Training on chunk 6
2025-04-23 12:03:55,676 - INFO - __main__ - Using 2 epochs for training on chunk 6
2025-04-23 12:05:32,341 - INFO - __main__ - Chunk 6 validation - Loss: 0.008870801888406277, MAE: 0.06552954018115997
2025-04-23 12:05:32,505 - INFO - __main__ - Processing chunk 7/7: rows 17580 to 18738
2025-04-23 12:05:32,506 - INFO - __main__ - Chunk 7 size: 1158 rows
2025-04-23 12:05:34,375 - INFO - __main__ - Created 1089 sequences from chunk 7
2025-04-23 12:05:34,381 - INFO - __main__ - Chunk 7 data shapes - X_train: (871, 60, 19), y_train: (871, 10)
2025-04-23 12:05:34,381 - INFO - __main__ - Training on chunk 7
2025-04-23 12:05:34,382 - INFO - __main__ - Using 2 epochs for training on chunk 7
2025-04-23 12:06:10,239 - INFO - __main__ - Chunk 7 validation - Loss: 0.02371285855770111, MAE: 0.12280189245939255
2025-04-23 12:06:15,450 - INFO - __main__ - Final evaluation - Loss: 0.028129486367106438, MAE: 0.1298387050628662
2025-04-23 12:06:53,364 - ERROR - __main__ - Error getting models: 'NoneType' object has no attribute 'get'
2025-04-23 12:13:36,684 - INFO - __main__ - Logging to file enabled
2025-04-23 12:13:43,861 - ERROR - __main__ - Unhandled exception: 404 Not Found: The requested URL was not found on the server. If you entered the URL manually please check your spelling and try again.
2025-04-23 12:13:43,873 - ERROR - __main__ - Traceback: Traceback (most recent call last):
  File "/home/olex/.local/lib/python3.8/site-packages/flask/app.py", line 1823, in full_dispatch_request
    rv = self.dispatch_request()
  File "/home/olex/.local/lib/python3.8/site-packages/flask/app.py", line 1788, in dispatch_request
    self.raise_routing_exception(req)
  File "/home/olex/.local/lib/python3.8/site-packages/flask/app.py", line 1770, in raise_routing_exception
    raise request.routing_exception  # type: ignore
  File "/home/olex/.local/lib/python3.8/site-packages/flask/ctx.py", line 351, in match_request
    result = self.url_adapter.match(return_rule=True)  # type: ignore
  File "/home/olex/.local/lib/python3.8/site-packages/werkzeug/routing/map.py", line 624, in match
    raise NotFound() from None
werkzeug.exceptions.NotFound: 404 Not Found: The requested URL was not found on the server. If you entered the URL manually please check your spelling and try again.

2025-04-23 12:13:50,412 - INFO - __main__ - Initializing ModelTrainer
2025-04-23 12:13:52,807 - INFO - __main__ - Features generated successfully for 17961 rows
2025-04-23 12:13:52,809 - INFO - __main__ - Preparing training data
2025-04-23 12:13:52,810 - INFO - __main__ - Total data size: 17961 rows
2025-04-23 12:13:52,811 - INFO - __main__ - Fitting scalers on the entire dataset
2025-04-23 12:13:52,818 - INFO - __main__ - Using features: ['open', 'high', 'low', 'close', 'volume', 'sma_5', 'sma_20', 'ema_5', 'ema_20', 'rsi', 'macd', 'macd_signal', 'bb_middle', 'bb_upper', 'bb_lower', 'price_change', 'price_change_5', 'volume_change', 'volume_ma_5']
2025-04-23 12:13:52,914 - INFO - __main__ - Using sequence_length=60, prediction_horizon=10
2025-04-23 12:14:02,056 - INFO - __main__ - Initial X shape: (2931, 60, 19), y shape: (2931, 10)
2025-04-23 12:14:02,061 - INFO - __main__ - Input shape: (60, 19)
2025-04-23 12:14:02,065 - INFO - __main__ - Initializing models with input shape: (60, 19)
2025-04-23 12:14:02,085 - INFO - __main__ - Models initialized successfully
2025-04-23 12:14:02,090 - INFO - __main__ - Selected model: model1
2025-04-23 12:14:02,091 - INFO - __main__ - Model configured with batch_size=32
2025-04-23 12:14:02,119 - INFO - __main__ - Building and compiling model
2025-04-23 12:14:05,035 - INFO - __main__ - No GPUs found, using CPU
2025-04-23 12:14:05,035 - INFO - __main__ - Preparing to train on 7 chunks with dataset size: 17961 rows
2025-04-23 12:14:05,036 - INFO - __main__ - Chunk size: 3000, Overlap: 70, Effective chunk size: 2930
2025-04-23 12:14:05,037 - INFO - __main__ - Processing chunk 1/7: rows 0 to 3000
2025-04-23 12:14:05,038 - INFO - __main__ - Chunk 1 size: 3000 rows
2025-04-23 12:14:05,039 - INFO - __main__ - Skipping first chunk as it was used for initialization
2025-04-23 12:14:05,040 - INFO - __main__ - Processing chunk 2/7: rows 2930 to 5930
2025-04-23 12:14:05,050 - INFO - __main__ - Chunk 2 size: 3000 rows
2025-04-23 12:14:13,269 - INFO - __main__ - Created 2931 sequences from chunk 2
2025-04-23 12:14:13,288 - INFO - __main__ - Chunk 2 data shapes - X_train: (2344, 60, 19), y_train: (2344, 10)
2025-04-23 12:14:13,290 - INFO - __main__ - Training on chunk 2
2025-04-23 12:14:13,290 - INFO - __main__ - Using 2 epochs for training on chunk 2
2025-04-23 12:14:44,026 - ERROR - __main__ - Error getting models: 'NoneType' object has no attribute 'get'
2025-04-23 12:16:18,412 - INFO - __main__ - Chunk 2 validation - Loss: 0.02067539282143116, MAE: 0.10698317736387253
2025-04-23 12:16:19,494 - INFO - __main__ - Processing chunk 3/7: rows 5860 to 8860
2025-04-23 12:16:19,496 - INFO - __main__ - Chunk 3 size: 3000 rows
2025-04-23 12:16:25,431 - INFO - __main__ - Created 2931 sequences from chunk 3
2025-04-23 12:16:25,451 - INFO - __main__ - Chunk 3 data shapes - X_train: (2344, 60, 19), y_train: (2344, 10)
2025-04-23 12:16:25,452 - INFO - __main__ - Training on chunk 3
2025-04-23 12:16:25,452 - INFO - __main__ - Using 2 epochs for training on chunk 3
2025-04-23 12:18:12,984 - INFO - __main__ - Chunk 3 validation - Loss: 0.013114162720739841, MAE: 0.09050779044628143
2025-04-23 12:18:13,143 - INFO - __main__ - Processing chunk 4/7: rows 8790 to 11790
2025-04-23 12:18:13,145 - INFO - __main__ - Chunk 4 size: 3000 rows
2025-04-23 12:18:18,610 - INFO - __main__ - Created 2931 sequences from chunk 4
2025-04-23 12:18:18,630 - INFO - __main__ - Chunk 4 data shapes - X_train: (2344, 60, 19), y_train: (2344, 10)
2025-04-23 12:18:18,631 - INFO - __main__ - Training on chunk 4
2025-04-23 12:18:18,631 - INFO - __main__ - Using 2 epochs for training on chunk 4
2025-04-23 12:20:06,191 - INFO - __main__ - Chunk 4 validation - Loss: 0.01700286567211151, MAE: 0.0993821993470192
2025-04-23 12:20:06,346 - INFO - __main__ - Processing chunk 5/7: rows 11720 to 14720
2025-04-23 12:20:06,347 - INFO - __main__ - Chunk 5 size: 3000 rows
2025-04-23 12:20:11,891 - INFO - __main__ - Created 2931 sequences from chunk 5
2025-04-23 12:20:11,907 - INFO - __main__ - Chunk 5 data shapes - X_train: (2344, 60, 19), y_train: (2344, 10)
2025-04-23 12:20:11,908 - INFO - __main__ - Training on chunk 5
2025-04-23 12:20:11,908 - INFO - __main__ - Using 2 epochs for training on chunk 5
2025-04-23 12:21:57,038 - INFO - __main__ - Chunk 5 validation - Loss: 0.013482192531228065, MAE: 0.08769823610782623
2025-04-23 12:21:57,177 - INFO - __main__ - Processing chunk 6/7: rows 14650 to 17650
2025-04-23 12:21:57,178 - INFO - __main__ - Chunk 6 size: 3000 rows
2025-04-23 12:22:01,853 - INFO - __main__ - Created 2931 sequences from chunk 6
2025-04-23 12:22:01,871 - INFO - __main__ - Chunk 6 data shapes - X_train: (2344, 60, 19), y_train: (2344, 10)
2025-04-23 12:22:01,872 - INFO - __main__ - Training on chunk 6
2025-04-23 12:22:01,872 - INFO - __main__ - Using 2 epochs for training on chunk 6
2025-04-23 12:23:34,113 - INFO - __main__ - Chunk 6 validation - Loss: 0.014969092793762684, MAE: 0.09420421719551086
2025-04-23 12:23:34,253 - INFO - __main__ - Processing chunk 7/7: rows 17580 to 17961
2025-04-23 12:23:34,254 - INFO - __main__ - Chunk 7 size: 381 rows
2025-04-23 12:23:34,753 - INFO - __main__ - Created 312 sequences from chunk 7
2025-04-23 12:23:34,755 - INFO - __main__ - Chunk 7 data shapes - X_train: (249, 60, 19), y_train: (249, 10)
2025-04-23 12:23:34,755 - INFO - __main__ - Training on chunk 7
2025-04-23 12:23:34,755 - INFO - __main__ - Using 2 epochs for training on chunk 7
2025-04-23 12:23:44,759 - INFO - __main__ - Chunk 7 validation - Loss: 0.01616705022752285, MAE: 0.09992791712284088
2025-04-23 12:23:49,543 - INFO - __main__ - Final evaluation - Loss: 0.005588605999946594, MAE: 0.05760914087295532
2025-04-23 12:24:31,142 - ERROR - __main__ - Error getting models: 'NoneType' object has no attribute 'get'
2025-04-23 12:28:25,009 - INFO - __main__ - Logging to file enabled
2025-04-23 12:28:43,911 - ERROR - __main__ - Unhandled exception: 404 Not Found: The requested URL was not found on the server. If you entered the URL manually please check your spelling and try again.
2025-04-23 12:28:43,914 - ERROR - __main__ - Traceback: Traceback (most recent call last):
  File "/home/olex/.local/lib/python3.8/site-packages/flask/app.py", line 1823, in full_dispatch_request
    rv = self.dispatch_request()
  File "/home/olex/.local/lib/python3.8/site-packages/flask/app.py", line 1788, in dispatch_request
    self.raise_routing_exception(req)
  File "/home/olex/.local/lib/python3.8/site-packages/flask/app.py", line 1770, in raise_routing_exception
    raise request.routing_exception  # type: ignore
  File "/home/olex/.local/lib/python3.8/site-packages/flask/ctx.py", line 351, in match_request
    result = self.url_adapter.match(return_rule=True)  # type: ignore
  File "/home/olex/.local/lib/python3.8/site-packages/werkzeug/routing/map.py", line 624, in match
    raise NotFound() from None
werkzeug.exceptions.NotFound: 404 Not Found: The requested URL was not found on the server. If you entered the URL manually please check your spelling and try again.

2025-04-23 12:28:45,239 - ERROR - __main__ - Unhandled exception: 404 Not Found: The requested URL was not found on the server. If you entered the URL manually please check your spelling and try again.
2025-04-23 12:28:45,241 - ERROR - __main__ - Traceback: Traceback (most recent call last):
  File "/home/olex/.local/lib/python3.8/site-packages/flask/app.py", line 1823, in full_dispatch_request
    rv = self.dispatch_request()
  File "/home/olex/.local/lib/python3.8/site-packages/flask/app.py", line 1788, in dispatch_request
    self.raise_routing_exception(req)
  File "/home/olex/.local/lib/python3.8/site-packages/flask/app.py", line 1770, in raise_routing_exception
    raise request.routing_exception  # type: ignore
  File "/home/olex/.local/lib/python3.8/site-packages/flask/ctx.py", line 351, in match_request
    result = self.url_adapter.match(return_rule=True)  # type: ignore
  File "/home/olex/.local/lib/python3.8/site-packages/werkzeug/routing/map.py", line 624, in match
    raise NotFound() from None
werkzeug.exceptions.NotFound: 404 Not Found: The requested URL was not found on the server. If you entered the URL manually please check your spelling and try again.

2025-04-23 12:28:52,410 - INFO - __main__ - Initializing ModelTrainer
2025-04-23 12:28:54,270 - INFO - __main__ - Features generated successfully for 17961 rows
2025-04-23 12:28:54,272 - INFO - __main__ - Preparing training data
2025-04-23 12:28:54,273 - INFO - __main__ - Total data size: 17961 rows
2025-04-23 12:28:54,275 - INFO - __main__ - Fitting scalers on the entire dataset
2025-04-23 12:28:54,277 - INFO - __main__ - Using features: ['open', 'high', 'low', 'close', 'volume', 'sma_5', 'sma_20', 'ema_5', 'ema_20', 'rsi', 'macd', 'macd_signal', 'bb_middle', 'bb_upper', 'bb_lower', 'price_change', 'price_change_5', 'volume_change', 'volume_ma_5']
2025-04-23 12:28:54,320 - INFO - __main__ - Using sequence_length=60, prediction_horizon=10
2025-04-23 12:29:02,805 - INFO - __main__ - Initial X shape: (2931, 60, 19), y shape: (2931, 10)
2025-04-23 12:29:02,816 - INFO - __main__ - Input shape: (60, 19)
2025-04-23 12:29:02,817 - INFO - __main__ - Initializing models with input shape: (60, 19)
2025-04-23 12:29:02,852 - INFO - __main__ - Models initialized successfully
2025-04-23 12:29:02,853 - INFO - __main__ - Selected model: model1
2025-04-23 12:29:02,854 - INFO - __main__ - Model configured with batch_size=32
2025-04-23 12:29:02,875 - INFO - __main__ - Building and compiling model
2025-04-23 12:29:05,522 - INFO - __main__ - No GPUs found, using CPU
2025-04-23 12:29:05,523 - INFO - __main__ - Preparing to train on 7 chunks with dataset size: 17961 rows
2025-04-23 12:29:05,524 - INFO - __main__ - Chunk size: 3000, Overlap: 70, Effective chunk size: 2930
2025-04-23 12:29:05,534 - INFO - __main__ - Processing chunk 1/7: rows 0 to 3000
2025-04-23 12:29:05,535 - INFO - __main__ - Chunk 1 size: 3000 rows
2025-04-23 12:29:05,536 - INFO - __main__ - Skipping first chunk as it was used for initialization
2025-04-23 12:29:05,537 - INFO - __main__ - Processing chunk 2/7: rows 2930 to 5930
2025-04-23 12:29:05,538 - INFO - __main__ - Chunk 2 size: 3000 rows
2025-04-23 12:29:12,755 - INFO - __main__ - Created 2931 sequences from chunk 2
2025-04-23 12:29:12,785 - INFO - __main__ - Chunk 2 data shapes - X_train: (2344, 60, 19), y_train: (2344, 10)
2025-04-23 12:29:12,788 - INFO - __main__ - Training on chunk 2
2025-04-23 12:29:12,790 - INFO - __main__ - Using 2 epochs for training on chunk 2
2025-04-23 12:29:48,954 - ERROR - __main__ - Error getting models: 'NoneType' object has no attribute 'get'
2025-04-23 12:31:07,981 - INFO - __main__ - Chunk 2 validation - Loss: 0.020609211176633835, MAE: 0.10691501945257187
2025-04-23 12:31:08,868 - INFO - __main__ - Processing chunk 3/7: rows 5860 to 8860
2025-04-23 12:31:08,869 - INFO - __main__ - Chunk 3 size: 3000 rows
2025-04-23 12:31:13,662 - INFO - __main__ - Created 2931 sequences from chunk 3
2025-04-23 12:31:13,679 - INFO - __main__ - Chunk 3 data shapes - X_train: (2344, 60, 19), y_train: (2344, 10)
2025-04-23 12:31:13,679 - INFO - __main__ - Training on chunk 3
2025-04-23 12:31:13,680 - INFO - __main__ - Using 2 epochs for training on chunk 3
2025-04-23 12:32:46,262 - INFO - __main__ - Chunk 3 validation - Loss: 0.01322739478200674, MAE: 0.0908622071146965
2025-04-23 12:32:46,402 - INFO - __main__ - Processing chunk 4/7: rows 8790 to 11790
2025-04-23 12:32:46,403 - INFO - __main__ - Chunk 4 size: 3000 rows
2025-04-23 12:32:51,427 - INFO - __main__ - Created 2931 sequences from chunk 4
2025-04-23 12:32:51,444 - INFO - __main__ - Chunk 4 data shapes - X_train: (2344, 60, 19), y_train: (2344, 10)
2025-04-23 12:32:51,445 - INFO - __main__ - Training on chunk 4
2025-04-23 12:32:51,445 - INFO - __main__ - Using 2 epochs for training on chunk 4
2025-04-23 12:34:24,249 - INFO - __main__ - Chunk 4 validation - Loss: 0.016842583194375038, MAE: 0.09816914796829224
2025-04-23 12:34:24,395 - INFO - __main__ - Processing chunk 5/7: rows 11720 to 14720
2025-04-23 12:34:24,396 - INFO - __main__ - Chunk 5 size: 3000 rows
2025-04-23 12:34:29,042 - INFO - __main__ - Created 2931 sequences from chunk 5
2025-04-23 12:34:29,055 - INFO - __main__ - Chunk 5 data shapes - X_train: (2344, 60, 19), y_train: (2344, 10)
2025-04-23 12:34:29,056 - INFO - __main__ - Training on chunk 5
2025-04-23 12:34:29,056 - INFO - __main__ - Using 2 epochs for training on chunk 5
2025-04-23 12:36:02,559 - INFO - __main__ - Chunk 5 validation - Loss: 0.013922267593443394, MAE: 0.09114508330821991
2025-04-23 12:36:02,713 - INFO - __main__ - Processing chunk 6/7: rows 14650 to 17650
2025-04-23 12:36:02,714 - INFO - __main__ - Chunk 6 size: 3000 rows
2025-04-23 12:36:07,364 - INFO - __main__ - Created 2931 sequences from chunk 6
2025-04-23 12:36:07,379 - INFO - __main__ - Chunk 6 data shapes - X_train: (2344, 60, 19), y_train: (2344, 10)
2025-04-23 12:36:07,380 - INFO - __main__ - Training on chunk 6
2025-04-23 12:36:07,380 - INFO - __main__ - Using 2 epochs for training on chunk 6
2025-04-23 12:37:40,333 - INFO - __main__ - Chunk 6 validation - Loss: 0.014840628020465374, MAE: 0.09345131367444992
2025-04-23 12:37:40,475 - INFO - __main__ - Processing chunk 7/7: rows 17580 to 17961
2025-04-23 12:37:40,476 - INFO - __main__ - Chunk 7 size: 381 rows
2025-04-23 12:37:40,986 - INFO - __main__ - Created 312 sequences from chunk 7
2025-04-23 12:37:40,988 - INFO - __main__ - Chunk 7 data shapes - X_train: (249, 60, 19), y_train: (249, 10)
2025-04-23 12:37:40,988 - INFO - __main__ - Training on chunk 7
2025-04-23 12:37:40,988 - INFO - __main__ - Using 2 epochs for training on chunk 7
2025-04-23 12:37:51,322 - INFO - __main__ - Chunk 7 validation - Loss: 0.015085251070559025, MAE: 0.09678896516561508
2025-04-23 12:37:56,258 - INFO - __main__ - Final evaluation - Loss: 0.005710991565138102, MAE: 0.058977942913770676
2025-04-23 12:38:44,751 - ERROR - __main__ - Error getting models: 'NoneType' object has no attribute 'get'
2025-04-23 12:41:06,017 - INFO - __main__ - Logging to file enabled
2025-04-23 12:41:12,253 - ERROR - __main__ - Unhandled exception: 404 Not Found: The requested URL was not found on the server. If you entered the URL manually please check your spelling and try again.
2025-04-23 12:41:12,259 - ERROR - __main__ - Traceback: Traceback (most recent call last):
  File "/home/olex/.local/lib/python3.8/site-packages/flask/app.py", line 1823, in full_dispatch_request
    rv = self.dispatch_request()
  File "/home/olex/.local/lib/python3.8/site-packages/flask/app.py", line 1788, in dispatch_request
    self.raise_routing_exception(req)
  File "/home/olex/.local/lib/python3.8/site-packages/flask/app.py", line 1770, in raise_routing_exception
    raise request.routing_exception  # type: ignore
  File "/home/olex/.local/lib/python3.8/site-packages/flask/ctx.py", line 351, in match_request
    result = self.url_adapter.match(return_rule=True)  # type: ignore
  File "/home/olex/.local/lib/python3.8/site-packages/werkzeug/routing/map.py", line 624, in match
    raise NotFound() from None
werkzeug.exceptions.NotFound: 404 Not Found: The requested URL was not found on the server. If you entered the URL manually please check your spelling and try again.

2025-04-23 12:41:13,735 - ERROR - __main__ - Unhandled exception: 404 Not Found: The requested URL was not found on the server. If you entered the URL manually please check your spelling and try again.
2025-04-23 12:41:13,746 - ERROR - __main__ - Traceback: Traceback (most recent call last):
  File "/home/olex/.local/lib/python3.8/site-packages/flask/app.py", line 1823, in full_dispatch_request
    rv = self.dispatch_request()
  File "/home/olex/.local/lib/python3.8/site-packages/flask/app.py", line 1788, in dispatch_request
    self.raise_routing_exception(req)
  File "/home/olex/.local/lib/python3.8/site-packages/flask/app.py", line 1770, in raise_routing_exception
    raise request.routing_exception  # type: ignore
  File "/home/olex/.local/lib/python3.8/site-packages/flask/ctx.py", line 351, in match_request
    result = self.url_adapter.match(return_rule=True)  # type: ignore
  File "/home/olex/.local/lib/python3.8/site-packages/werkzeug/routing/map.py", line 624, in match
    raise NotFound() from None
werkzeug.exceptions.NotFound: 404 Not Found: The requested URL was not found on the server. If you entered the URL manually please check your spelling and try again.

2025-04-23 12:41:15,365 - INFO - __main__ - Initializing ModelTrainer
2025-04-23 12:41:17,043 - INFO - __main__ - Features generated successfully for 18738 rows
2025-04-23 12:41:17,055 - INFO - __main__ - Preparing training data
2025-04-23 12:41:17,069 - INFO - __main__ - Total data size: 18738 rows
2025-04-23 12:41:17,082 - INFO - __main__ - Fitting scalers on the entire dataset
2025-04-23 12:41:17,084 - INFO - __main__ - Using features: ['open', 'high', 'low', 'close', 'volume', 'sma_5', 'sma_20', 'ema_5', 'ema_20', 'rsi', 'macd', 'macd_signal', 'bb_middle', 'bb_upper', 'bb_lower', 'price_change', 'price_change_5', 'volume_change', 'volume_ma_5']
2025-04-23 12:41:17,132 - INFO - __main__ - Using sequence_length=60, prediction_horizon=10
2025-04-23 12:41:25,653 - INFO - __main__ - Initial X shape: (2931, 60, 19), y shape: (2931, 10)
2025-04-23 12:41:25,663 - INFO - __main__ - Input shape: (60, 19)
2025-04-23 12:41:25,664 - INFO - __main__ - Initializing models with input shape: (60, 19)
2025-04-23 12:41:25,685 - INFO - __main__ - Models initialized successfully
2025-04-23 12:41:25,688 - INFO - __main__ - Selected model: model1
2025-04-23 12:41:25,688 - INFO - __main__ - Model configured with batch_size=32
2025-04-23 12:41:25,706 - INFO - __main__ - Building and compiling model
2025-04-23 12:41:28,229 - INFO - __main__ - No GPUs found, using CPU
2025-04-23 12:41:28,230 - INFO - __main__ - Preparing to train on 7 chunks with dataset size: 18738 rows
2025-04-23 12:41:28,230 - INFO - __main__ - Chunk size: 3000, Overlap: 70, Effective chunk size: 2930
2025-04-23 12:41:28,230 - INFO - __main__ - Processing chunk 1/7: rows 0 to 3000
2025-04-23 12:41:28,231 - INFO - __main__ - Chunk 1 size: 3000 rows
2025-04-23 12:41:28,231 - INFO - __main__ - Skipping first chunk as it was used for initialization
2025-04-23 12:41:28,232 - INFO - __main__ - Processing chunk 2/7: rows 2930 to 5930
2025-04-23 12:41:28,233 - INFO - __main__ - Chunk 2 size: 3000 rows
2025-04-23 12:41:35,793 - INFO - __main__ - Created 2931 sequences from chunk 2
2025-04-23 12:41:35,811 - INFO - __main__ - Chunk 2 data shapes - X_train: (2344, 60, 19), y_train: (2344, 10)
2025-04-23 12:41:35,814 - INFO - __main__ - Training on chunk 2
2025-04-23 12:41:35,816 - INFO - __main__ - Using 2 epochs for training on chunk 2
2025-04-23 12:43:35,985 - INFO - __main__ - Chunk 2 validation - Loss: 0.05337794870138168, MAE: 0.1799124777317047
2025-04-23 12:43:36,444 - INFO - __main__ - Processing chunk 3/7: rows 5860 to 8860
2025-04-23 12:43:36,445 - INFO - __main__ - Chunk 3 size: 3000 rows
2025-04-23 12:43:41,201 - INFO - __main__ - Created 2931 sequences from chunk 3
2025-04-23 12:43:41,215 - INFO - __main__ - Chunk 3 data shapes - X_train: (2344, 60, 19), y_train: (2344, 10)
2025-04-23 12:43:41,216 - INFO - __main__ - Training on chunk 3
2025-04-23 12:43:41,216 - INFO - __main__ - Using 2 epochs for training on chunk 3
2025-04-23 12:45:14,540 - INFO - __main__ - Chunk 3 validation - Loss: 0.0234481580555439, MAE: 0.1192171648144722
2025-04-23 12:45:14,741 - INFO - __main__ - Processing chunk 4/7: rows 8790 to 11790
2025-04-23 12:45:14,742 - INFO - __main__ - Chunk 4 size: 3000 rows
2025-04-23 12:45:19,676 - INFO - __main__ - Created 2931 sequences from chunk 4
2025-04-23 12:45:19,692 - INFO - __main__ - Chunk 4 data shapes - X_train: (2344, 60, 19), y_train: (2344, 10)
2025-04-23 12:45:19,693 - INFO - __main__ - Training on chunk 4
2025-04-23 12:45:19,693 - INFO - __main__ - Using 2 epochs for training on chunk 4
2025-04-23 12:46:54,254 - INFO - __main__ - Chunk 4 validation - Loss: 0.004285828676074743, MAE: 0.04635941982269287
2025-04-23 12:46:54,504 - INFO - __main__ - Processing chunk 5/7: rows 11720 to 14720
2025-04-23 12:46:54,507 - INFO - __main__ - Chunk 5 size: 3000 rows
2025-04-23 12:46:59,932 - INFO - __main__ - Created 2931 sequences from chunk 5
2025-04-23 12:46:59,946 - INFO - __main__ - Chunk 5 data shapes - X_train: (2344, 60, 19), y_train: (2344, 10)
2025-04-23 12:46:59,946 - INFO - __main__ - Training on chunk 5
2025-04-23 12:46:59,947 - INFO - __main__ - Using 2 epochs for training on chunk 5
2025-04-23 12:48:33,772 - INFO - __main__ - Chunk 5 validation - Loss: 0.005510047543793917, MAE: 0.054041787981987
2025-04-23 12:48:33,960 - INFO - __main__ - Processing chunk 6/7: rows 14650 to 17650
2025-04-23 12:48:33,961 - INFO - __main__ - Chunk 6 size: 3000 rows
2025-04-23 12:48:38,795 - INFO - __main__ - Created 2931 sequences from chunk 6
2025-04-23 12:48:38,809 - INFO - __main__ - Chunk 6 data shapes - X_train: (2344, 60, 19), y_train: (2344, 10)
2025-04-23 12:48:38,809 - INFO - __main__ - Training on chunk 6
2025-04-23 12:48:38,810 - INFO - __main__ - Using 2 epochs for training on chunk 6
2025-04-23 12:50:12,209 - INFO - __main__ - Chunk 6 validation - Loss: 0.009708411060273647, MAE: 0.06715648621320724
2025-04-23 12:50:12,401 - INFO - __main__ - Processing chunk 7/7: rows 17580 to 18738
2025-04-23 12:50:12,402 - INFO - __main__ - Chunk 7 size: 1158 rows
2025-04-23 12:50:14,208 - INFO - __main__ - Created 1089 sequences from chunk 7
2025-04-23 12:50:14,213 - INFO - __main__ - Chunk 7 data shapes - X_train: (871, 60, 19), y_train: (871, 10)
2025-04-23 12:50:14,214 - INFO - __main__ - Training on chunk 7
2025-04-23 12:50:14,214 - INFO - __main__ - Using 2 epochs for training on chunk 7
2025-04-23 12:50:48,662 - INFO - __main__ - Chunk 7 validation - Loss: 0.024955399334430695, MAE: 0.12540870904922485
2025-04-23 12:50:53,608 - INFO - __main__ - Final evaluation - Loss: 0.031125927343964577, MAE: 0.13519525527954102
2025-04-23 15:13:07,624 - INFO - __main__ - Logging to file enabled
2025-04-23 15:13:14,964 - ERROR - __main__ - Unhandled exception: 404 Not Found: The requested URL was not found on the server. If you entered the URL manually please check your spelling and try again.
2025-04-23 15:13:14,966 - ERROR - __main__ - Traceback: Traceback (most recent call last):
  File "/home/olex/.local/lib/python3.8/site-packages/flask/app.py", line 1823, in full_dispatch_request
    rv = self.dispatch_request()
  File "/home/olex/.local/lib/python3.8/site-packages/flask/app.py", line 1788, in dispatch_request
    self.raise_routing_exception(req)
  File "/home/olex/.local/lib/python3.8/site-packages/flask/app.py", line 1770, in raise_routing_exception
    raise request.routing_exception  # type: ignore
  File "/home/olex/.local/lib/python3.8/site-packages/flask/ctx.py", line 351, in match_request
    result = self.url_adapter.match(return_rule=True)  # type: ignore
  File "/home/olex/.local/lib/python3.8/site-packages/werkzeug/routing/map.py", line 624, in match
    raise NotFound() from None
werkzeug.exceptions.NotFound: 404 Not Found: The requested URL was not found on the server. If you entered the URL manually please check your spelling and try again.

2025-04-23 15:13:16,784 - ERROR - __main__ - Unhandled exception: 404 Not Found: The requested URL was not found on the server. If you entered the URL manually please check your spelling and try again.
2025-04-23 15:13:16,787 - ERROR - __main__ - Traceback: Traceback (most recent call last):
  File "/home/olex/.local/lib/python3.8/site-packages/flask/app.py", line 1823, in full_dispatch_request
    rv = self.dispatch_request()
  File "/home/olex/.local/lib/python3.8/site-packages/flask/app.py", line 1788, in dispatch_request
    self.raise_routing_exception(req)
  File "/home/olex/.local/lib/python3.8/site-packages/flask/app.py", line 1770, in raise_routing_exception
    raise request.routing_exception  # type: ignore
  File "/home/olex/.local/lib/python3.8/site-packages/flask/ctx.py", line 351, in match_request
    result = self.url_adapter.match(return_rule=True)  # type: ignore
  File "/home/olex/.local/lib/python3.8/site-packages/werkzeug/routing/map.py", line 624, in match
    raise NotFound() from None
werkzeug.exceptions.NotFound: 404 Not Found: The requested URL was not found on the server. If you entered the URL manually please check your spelling and try again.

2025-04-23 15:13:22,172 - INFO - __main__ - Initializing ModelTrainer
2025-04-23 15:13:23,859 - INFO - __main__ - Features generated successfully for 16933 rows
2025-04-23 15:13:23,861 - INFO - __main__ - Preparing training data
2025-04-23 15:13:23,862 - INFO - __main__ - Total data size: 16933 rows
2025-04-23 15:13:23,868 - INFO - __main__ - Fitting scalers on the entire dataset
2025-04-23 15:13:23,872 - INFO - __main__ - Using features: ['open', 'high', 'low', 'close', 'volume', 'sma_5', 'sma_20', 'ema_5', 'ema_20', 'rsi', 'macd', 'macd_signal', 'bb_middle', 'bb_upper', 'bb_lower', 'price_change', 'price_change_5', 'volume_change', 'volume_ma_5']
2025-04-23 15:13:23,911 - INFO - __main__ - Using sequence_length=60, prediction_horizon=10
2025-04-23 15:13:31,701 - INFO - __main__ - Initial X shape: (2931, 60, 19), y shape: (2931, 10)
2025-04-23 15:13:31,706 - INFO - __main__ - Input shape: (60, 19)
2025-04-23 15:13:31,707 - INFO - __main__ - Initializing models with input shape: (60, 19)
2025-04-23 15:13:31,739 - INFO - __main__ - Models initialized successfully
2025-04-23 15:13:31,740 - INFO - __main__ - Selected model: model1
2025-04-23 15:13:31,740 - INFO - __main__ - Model configured with batch_size=32
2025-04-23 15:13:31,776 - INFO - __main__ - Building and compiling model
2025-04-23 15:13:34,959 - INFO - __main__ - No GPUs found, using CPU
2025-04-23 15:13:34,960 - INFO - __main__ - Preparing to train on 6 chunks with dataset size: 16933 rows
2025-04-23 15:13:34,961 - INFO - __main__ - Chunk size: 3000, Overlap: 70, Effective chunk size: 2930
2025-04-23 15:13:34,964 - INFO - __main__ - Processing chunk 1/6: rows 0 to 3000
2025-04-23 15:13:34,967 - INFO - __main__ - Chunk 1 size: 3000 rows
2025-04-23 15:13:34,968 - INFO - __main__ - Skipping first chunk as it was used for initialization
2025-04-23 15:13:34,971 - INFO - __main__ - Processing chunk 2/6: rows 2930 to 5930
2025-04-23 15:13:34,973 - INFO - __main__ - Chunk 2 size: 3000 rows
2025-04-23 15:13:43,575 - INFO - __main__ - Created 2931 sequences from chunk 2
2025-04-23 15:13:43,598 - INFO - __main__ - Chunk 2 data shapes - X_train: (2344, 60, 19), y_train: (2344, 10)
2025-04-23 15:13:43,599 - INFO - __main__ - Training on chunk 2
2025-04-23 15:13:43,604 - INFO - __main__ - Using 2 epochs for training on chunk 2
2025-04-23 15:15:45,195 - INFO - __main__ - Chunk 2 validation - Loss: 0.02620568312704563, MAE: 0.12590789794921875
2025-04-23 15:15:45,895 - INFO - __main__ - Processing chunk 3/6: rows 5860 to 8860
2025-04-23 15:15:45,896 - INFO - __main__ - Chunk 3 size: 3000 rows
2025-04-23 15:15:50,770 - INFO - __main__ - Created 2931 sequences from chunk 3
2025-04-23 15:15:50,787 - INFO - __main__ - Chunk 3 data shapes - X_train: (2344, 60, 19), y_train: (2344, 10)
2025-04-23 15:15:50,788 - INFO - __main__ - Training on chunk 3
2025-04-23 15:15:50,788 - INFO - __main__ - Using 2 epochs for training on chunk 3
2025-04-23 15:17:26,835 - INFO - __main__ - Chunk 3 validation - Loss: 0.03364232927560806, MAE: 0.14334620535373688
2025-04-23 15:17:27,024 - INFO - __main__ - Processing chunk 4/6: rows 8790 to 11790
2025-04-23 15:17:27,025 - INFO - __main__ - Chunk 4 size: 3000 rows
2025-04-23 15:17:31,944 - INFO - __main__ - Created 2931 sequences from chunk 4
2025-04-23 15:17:31,959 - INFO - __main__ - Chunk 4 data shapes - X_train: (2344, 60, 19), y_train: (2344, 10)
2025-04-23 15:17:31,960 - INFO - __main__ - Training on chunk 4
2025-04-23 15:17:31,960 - INFO - __main__ - Using 2 epochs for training on chunk 4
2025-04-23 15:19:07,303 - INFO - __main__ - Chunk 4 validation - Loss: 0.02373560518026352, MAE: 0.12142490595579147
2025-04-23 15:19:07,498 - INFO - __main__ - Processing chunk 5/6: rows 11720 to 14720
2025-04-23 15:19:07,499 - INFO - __main__ - Chunk 5 size: 3000 rows
2025-04-23 15:19:12,893 - INFO - __main__ - Created 2931 sequences from chunk 5
2025-04-23 15:19:12,908 - INFO - __main__ - Chunk 5 data shapes - X_train: (2344, 60, 19), y_train: (2344, 10)
2025-04-23 15:19:12,909 - INFO - __main__ - Training on chunk 5
2025-04-23 15:19:12,909 - INFO - __main__ - Using 2 epochs for training on chunk 5
2025-04-23 15:20:47,960 - INFO - __main__ - Chunk 5 validation - Loss: 0.011294116266071796, MAE: 0.08292537927627563
2025-04-23 15:20:48,159 - INFO - __main__ - Processing chunk 6/6: rows 14650 to 16933
2025-04-23 15:20:48,160 - INFO - __main__ - Chunk 6 size: 2283 rows
2025-04-23 15:20:52,527 - INFO - __main__ - Created 2214 sequences from chunk 6
2025-04-23 15:20:52,538 - INFO - __main__ - Chunk 6 data shapes - X_train: (1771, 60, 19), y_train: (1771, 10)
2025-04-23 15:20:52,539 - INFO - __main__ - Training on chunk 6
2025-04-23 15:20:52,540 - INFO - __main__ - Using 2 epochs for training on chunk 6
2025-04-23 15:22:04,851 - INFO - __main__ - Chunk 6 validation - Loss: 0.016691910102963448, MAE: 0.10089945793151855
2025-04-23 15:22:10,081 - INFO - __main__ - Final evaluation - Loss: 0.011329729110002518, MAE: 0.08364306390285492
2025-04-23 15:24:25,551 - INFO - __main__ - Features generated successfully for 16933 rows
2025-04-23 15:24:25,551 - INFO - __main__ - Preparing training data
2025-04-23 15:24:25,551 - INFO - __main__ - Total data size: 16933 rows
2025-04-23 15:24:25,552 - INFO - __main__ - Fitting scalers on the entire dataset
2025-04-23 15:24:25,553 - INFO - __main__ - Using features: ['open', 'high', 'low', 'close', 'volume', 'sma_5', 'sma_20', 'ema_5', 'ema_20', 'rsi', 'macd', 'macd_signal', 'bb_middle', 'bb_upper', 'bb_lower', 'price_change', 'price_change_5', 'volume_change', 'volume_ma_5']
2025-04-23 15:24:25,563 - INFO - __main__ - Using sequence_length=60, prediction_horizon=10
2025-04-23 15:24:30,493 - INFO - __main__ - Initial X shape: (2931, 60, 19), y shape: (2931, 10)
2025-04-23 15:24:30,497 - INFO - __main__ - Input shape: (60, 19)
2025-04-23 15:24:30,497 - INFO - __main__ - Initializing models with input shape: (60, 19)
2025-04-23 15:24:30,505 - INFO - __main__ - Models initialized successfully
2025-04-23 15:24:30,505 - INFO - __main__ - Selected model: model2
2025-04-23 15:24:30,505 - INFO - __main__ - Using extended training configuration for model2: batch_size=64, epochs=default
2025-04-23 15:24:30,506 - INFO - __main__ - Model configured with batch_size=64
2025-04-23 15:24:30,517 - INFO - __main__ - Building and compiling model
2025-04-23 15:24:31,971 - INFO - __main__ - No GPUs found, using CPU
2025-04-23 15:24:31,972 - INFO - __main__ - Preparing to train on 6 chunks with dataset size: 16933 rows
2025-04-23 15:24:31,973 - INFO - __main__ - Chunk size: 3000, Overlap: 70, Effective chunk size: 2930
2025-04-23 15:24:31,973 - INFO - __main__ - Processing chunk 1/6: rows 0 to 3000
2025-04-23 15:24:31,974 - INFO - __main__ - Chunk 1 size: 3000 rows
2025-04-23 15:24:31,974 - INFO - __main__ - Skipping first chunk as it was used for initialization
2025-04-23 15:24:31,974 - INFO - __main__ - Processing chunk 2/6: rows 2930 to 5930
2025-04-23 15:24:31,975 - INFO - __main__ - Chunk 2 size: 3000 rows
2025-04-23 15:24:36,888 - INFO - __main__ - Created 2931 sequences from chunk 2
2025-04-23 15:24:36,904 - INFO - __main__ - Chunk 2 data shapes - X_train: (2344, 60, 19), y_train: (2344, 10)
2025-04-23 15:24:36,905 - INFO - __main__ - Training on chunk 2
2025-04-23 15:24:36,905 - INFO - __main__ - Using 10 epochs for training on chunk 2
2025-04-23 15:47:20,752 - INFO - __main__ - Chunk 2 validation - Loss: 0.0011511603370308876, MAE: 0.02016637474298477
2025-04-23 15:47:21,046 - INFO - __main__ - Processing chunk 3/6: rows 5860 to 8860
2025-04-23 15:47:21,047 - INFO - __main__ - Chunk 3 size: 3000 rows
2025-04-23 15:47:29,953 - INFO - __main__ - Created 2931 sequences from chunk 3
2025-04-23 15:47:30,701 - INFO - __main__ - Chunk 3 data shapes - X_train: (2344, 60, 19), y_train: (2344, 10)
2025-04-23 15:47:30,702 - INFO - __main__ - Training on chunk 3
2025-04-23 15:47:30,702 - INFO - __main__ - Using 10 epochs for training on chunk 3
2025-04-23 16:10:05,492 - INFO - __main__ - Chunk 3 validation - Loss: 0.006551340222358704, MAE: 0.07349356263875961
2025-04-23 16:10:05,698 - INFO - __main__ - Processing chunk 4/6: rows 8790 to 11790
2025-04-23 16:10:05,699 - INFO - __main__ - Chunk 4 size: 3000 rows
2025-04-23 16:10:10,383 - INFO - __main__ - Created 2931 sequences from chunk 4
2025-04-23 16:10:10,396 - INFO - __main__ - Chunk 4 data shapes - X_train: (2344, 60, 19), y_train: (2344, 10)
2025-04-23 16:10:10,397 - INFO - __main__ - Training on chunk 4
2025-04-23 16:10:10,397 - INFO - __main__ - Using 10 epochs for training on chunk 4
2025-04-23 16:30:54,438 - INFO - __main__ - Chunk 4 validation - Loss: 0.0032476417254656553, MAE: 0.0485655814409256
2025-04-23 16:30:54,642 - INFO - __main__ - Processing chunk 5/6: rows 11720 to 14720
2025-04-23 16:30:54,643 - INFO - __main__ - Chunk 5 size: 3000 rows
2025-04-23 16:31:00,129 - INFO - __main__ - Created 2931 sequences from chunk 5
2025-04-23 16:31:00,145 - INFO - __main__ - Chunk 5 data shapes - X_train: (2344, 60, 19), y_train: (2344, 10)
2025-04-23 16:31:00,145 - INFO - __main__ - Training on chunk 5
2025-04-23 16:31:00,146 - INFO - __main__ - Using 10 epochs for training on chunk 5
2025-04-23 16:51:47,700 - INFO - __main__ - Chunk 5 validation - Loss: 0.0016652261838316917, MAE: 0.03128928691148758
2025-04-23 16:51:48,042 - INFO - __main__ - Processing chunk 6/6: rows 14650 to 16933
2025-04-23 16:51:48,042 - INFO - __main__ - Chunk 6 size: 2283 rows
2025-04-23 16:51:51,609 - INFO - __main__ - Created 2214 sequences from chunk 6
2025-04-23 16:51:51,624 - INFO - __main__ - Chunk 6 data shapes - X_train: (1771, 60, 19), y_train: (1771, 10)
2025-04-23 16:51:51,624 - INFO - __main__ - Training on chunk 6
2025-04-23 16:51:51,625 - INFO - __main__ - Using 10 epochs for training on chunk 6
2025-04-23 17:07:27,167 - INFO - __main__ - Chunk 6 validation - Loss: 0.002384190447628498, MAE: 0.03932002931833267
2025-04-23 17:07:37,205 - INFO - __main__ - Final evaluation - Loss: 0.13702459633350372, MAE: 0.349016010761261
2025-04-23 17:39:25,990 - INFO - __main__ - Logging to file enabled
2025-04-23 17:39:38,751 - ERROR - __main__ - Unhandled exception: 404 Not Found: The requested URL was not found on the server. If you entered the URL manually please check your spelling and try again.
2025-04-23 17:39:38,814 - ERROR - __main__ - Traceback: Traceback (most recent call last):
  File "/home/olex/.local/lib/python3.8/site-packages/flask/app.py", line 1823, in full_dispatch_request
    rv = self.dispatch_request()
  File "/home/olex/.local/lib/python3.8/site-packages/flask/app.py", line 1788, in dispatch_request
    self.raise_routing_exception(req)
  File "/home/olex/.local/lib/python3.8/site-packages/flask/app.py", line 1770, in raise_routing_exception
    raise request.routing_exception  # type: ignore
  File "/home/olex/.local/lib/python3.8/site-packages/flask/ctx.py", line 351, in match_request
    result = self.url_adapter.match(return_rule=True)  # type: ignore
  File "/home/olex/.local/lib/python3.8/site-packages/werkzeug/routing/map.py", line 624, in match
    raise NotFound() from None
werkzeug.exceptions.NotFound: 404 Not Found: The requested URL was not found on the server. If you entered the URL manually please check your spelling and try again.

2025-04-23 17:39:41,949 - INFO - __main__ - Initializing ModelTrainer
2025-04-23 17:39:44,023 - INFO - __main__ - Features generated successfully for 18738 rows
2025-04-23 17:39:44,023 - INFO - __main__ - Preparing training data
2025-04-23 17:39:44,024 - INFO - __main__ - Total data size: 18738 rows
2025-04-23 17:39:44,025 - INFO - __main__ - Fitting scalers on the entire dataset
2025-04-23 17:39:44,029 - INFO - __main__ - Using features: ['open', 'high', 'low', 'close', 'volume', 'sma_5', 'sma_20', 'ema_5', 'ema_20', 'rsi', 'macd', 'macd_signal', 'bb_middle', 'bb_upper', 'bb_lower', 'price_change', 'price_change_5', 'volume_change', 'volume_ma_5']
2025-04-23 17:39:44,088 - INFO - __main__ - Using sequence_length=60, prediction_horizon=10
2025-04-23 17:39:44,098 - ERROR - __main__ - Error during data preparation: local variable 'chunk_size' referenced before assignment
2025-04-23 17:39:44,119 - ERROR - __main__ - Detailed traceback: Traceback (most recent call last):
  File "app.py", line 313, in start_training
    initial_data = processed_data.iloc[:chunk_size]
UnboundLocalError: local variable 'chunk_size' referenced before assignment

2025-04-23 17:44:36,735 - INFO - __main__ - Logging to file enabled
2025-04-23 17:44:51,184 - ERROR - __main__ - Unhandled exception: 404 Not Found: The requested URL was not found on the server. If you entered the URL manually please check your spelling and try again.
2025-04-23 17:44:51,217 - ERROR - __main__ - Traceback: Traceback (most recent call last):
  File "/home/olex/.local/lib/python3.8/site-packages/flask/app.py", line 1823, in full_dispatch_request
    rv = self.dispatch_request()
  File "/home/olex/.local/lib/python3.8/site-packages/flask/app.py", line 1788, in dispatch_request
    self.raise_routing_exception(req)
  File "/home/olex/.local/lib/python3.8/site-packages/flask/app.py", line 1770, in raise_routing_exception
    raise request.routing_exception  # type: ignore
  File "/home/olex/.local/lib/python3.8/site-packages/flask/ctx.py", line 351, in match_request
    result = self.url_adapter.match(return_rule=True)  # type: ignore
  File "/home/olex/.local/lib/python3.8/site-packages/werkzeug/routing/map.py", line 624, in match
    raise NotFound() from None
werkzeug.exceptions.NotFound: 404 Not Found: The requested URL was not found on the server. If you entered the URL manually please check your spelling and try again.

2025-04-23 17:44:54,495 - INFO - __main__ - Initializing ModelTrainer
2025-04-23 17:44:56,624 - INFO - __main__ - Features generated successfully for 16933 rows
2025-04-23 17:44:56,631 - INFO - __main__ - Preparing training data
2025-04-23 17:44:56,633 - INFO - __main__ - Total data size: 16933 rows
2025-04-23 17:44:56,634 - INFO - __main__ - Fitting scalers on the entire dataset
2025-04-23 17:44:56,635 - INFO - __main__ - Using features: ['open', 'high', 'low', 'close', 'volume', 'sma_5', 'sma_20', 'ema_5', 'ema_20', 'rsi', 'macd', 'macd_signal', 'bb_middle', 'bb_upper', 'bb_lower', 'price_change', 'price_change_5', 'volume_change', 'volume_ma_5']
2025-04-23 17:44:56,709 - INFO - __main__ - Using sequence_length=60, prediction_horizon=10
2025-04-23 17:45:03,808 - INFO - __main__ - Initial X shape: (2931, 60, 19), y shape: (2931, 10)
2025-04-23 17:45:03,814 - INFO - __main__ - Input shape: (60, 19)
2025-04-23 17:45:03,815 - INFO - __main__ - Initializing models with input shape: (60, 19)
2025-04-23 17:45:03,826 - INFO - __main__ - Models initialized successfully
2025-04-23 17:45:03,827 - INFO - __main__ - Selected model: model2
2025-04-23 17:45:03,828 - INFO - __main__ - Using optimized config for Model 2 (BozdoganCAIC): batch_size=128, epochs=15, chunk_size=3500
2025-04-23 17:45:03,830 - INFO - __main__ - Model configured with batch_size=128
2025-04-23 17:45:03,845 - INFO - __main__ - Building and compiling model
2025-04-23 17:45:10,384 - INFO - __main__ - No GPUs found, using CPU
2025-04-23 17:45:10,385 - INFO - __main__ - Preparing to train on 5 chunks with dataset size: 16933 rows
2025-04-23 17:45:10,386 - INFO - __main__ - Chunk size: 3500, Overlap: 70, Effective chunk size: 3430
2025-04-23 17:45:10,387 - INFO - __main__ - Processing chunk 1/5: rows 0 to 3500
2025-04-23 17:45:10,389 - INFO - __main__ - Chunk 1 size: 3500 rows
2025-04-23 17:45:10,393 - INFO - __main__ - Skipping first chunk as it was used for initialization
2025-04-23 17:45:10,395 - INFO - __main__ - Processing chunk 2/5: rows 3430 to 6930
2025-04-23 17:45:10,400 - INFO - __main__ - Chunk 2 size: 3500 rows
2025-04-23 17:45:19,553 - INFO - __main__ - Created 3431 sequences from chunk 2
2025-04-23 17:45:19,593 - INFO - __main__ - Chunk 2 data shapes - X_train: (2744, 60, 19), y_train: (2744, 10)
2025-04-23 17:45:19,600 - INFO - __main__ - Training on chunk 2
2025-04-23 17:45:19,603 - INFO - __main__ - Using 15 epochs for training on chunk 2
2025-04-23 18:22:25,655 - INFO - __main__ - Chunk 2 validation - Loss: 0.0024994818959385157, MAE: 0.03578570485115051
2025-04-23 18:22:25,909 - INFO - __main__ - Processing chunk 3/5: rows 6860 to 10360
2025-04-23 18:22:25,910 - INFO - __main__ - Chunk 3 size: 3500 rows
2025-04-23 18:22:31,390 - INFO - __main__ - Created 3431 sequences from chunk 3
2025-04-23 18:22:31,407 - INFO - __main__ - Chunk 3 data shapes - X_train: (2744, 60, 19), y_train: (2744, 10)
2025-04-23 18:22:31,407 - INFO - __main__ - Training on chunk 3
2025-04-23 18:22:31,408 - INFO - __main__ - Using 15 epochs for training on chunk 3
2025-04-23 18:59:40,908 - INFO - __main__ - Chunk 3 validation - Loss: 0.0027794898487627506, MAE: 0.040266867727041245
2025-04-23 18:59:41,138 - INFO - __main__ - Processing chunk 4/5: rows 10290 to 13790
2025-04-23 18:59:41,139 - INFO - __main__ - Chunk 4 size: 3500 rows
2025-04-23 18:59:46,629 - INFO - __main__ - Created 3431 sequences from chunk 4
2025-04-23 18:59:46,641 - INFO - __main__ - Chunk 4 data shapes - X_train: (2744, 60, 19), y_train: (2744, 10)
2025-04-23 18:59:46,641 - INFO - __main__ - Training on chunk 4
2025-04-23 18:59:46,641 - INFO - __main__ - Using 15 epochs for training on chunk 4
2025-04-23 19:35:48,904 - INFO - __main__ - Chunk 4 validation - Loss: 0.0008186512277461588, MAE: 0.013440961018204689
2025-04-23 19:35:49,124 - INFO - __main__ - Processing chunk 5/5: rows 13720 to 16933
2025-04-23 19:35:49,125 - INFO - __main__ - Chunk 5 size: 3213 rows
2025-04-23 19:35:54,512 - INFO - __main__ - Created 3144 sequences from chunk 5
2025-04-23 19:35:54,523 - INFO - __main__ - Chunk 5 data shapes - X_train: (2515, 60, 19), y_train: (2515, 10)
2025-04-23 19:35:54,524 - INFO - __main__ - Training on chunk 5
2025-04-23 19:35:54,524 - INFO - __main__ - Using 15 epochs for training on chunk 5
2025-04-23 20:08:40,957 - INFO - __main__ - Chunk 5 validation - Loss: 0.029049474745988846, MAE: 0.15891101956367493
2025-04-23 20:08:51,872 - INFO - __main__ - Final evaluation - Loss: 0.058822084218263626, MAE: 0.19313673675060272
2025-04-23 20:57:45,324 - INFO - __main__ - Features generated successfully for 17961 rows
2025-04-23 20:57:45,324 - INFO - __main__ - Preparing training data
2025-04-23 20:57:45,325 - INFO - __main__ - Total data size: 17961 rows
2025-04-23 20:57:45,325 - INFO - __main__ - Fitting scalers on the entire dataset
2025-04-23 20:57:45,326 - INFO - __main__ - Using features: ['open', 'high', 'low', 'close', 'volume', 'sma_5', 'sma_20', 'ema_5', 'ema_20', 'rsi', 'macd', 'macd_signal', 'bb_middle', 'bb_upper', 'bb_lower', 'price_change', 'price_change_5', 'volume_change', 'volume_ma_5']
2025-04-23 20:57:45,333 - INFO - __main__ - Using sequence_length=60, prediction_horizon=10
2025-04-23 20:57:49,816 - INFO - __main__ - Initial X shape: (2931, 60, 19), y shape: (2931, 10)
2025-04-23 20:57:49,821 - INFO - __main__ - Input shape: (60, 19)
2025-04-23 20:57:49,822 - INFO - __main__ - Initializing models with input shape: (60, 19)
2025-04-23 20:57:49,830 - INFO - __main__ - Models initialized successfully
2025-04-23 20:57:49,830 - INFO - __main__ - Selected model: model1
2025-04-23 20:57:49,830 - INFO - __main__ - Using optimized config for Model 1 (Bayesian): batch_size=64, epochs=12, chunk_size=3000
2025-04-23 20:57:49,831 - INFO - __main__ - Model configured with batch_size=64
2025-04-23 20:57:49,840 - INFO - __main__ - Building and compiling model
2025-04-23 20:57:50,531 - INFO - __main__ - No GPUs found, using CPU
2025-04-23 20:57:50,532 - INFO - __main__ - Preparing to train on 7 chunks with dataset size: 17961 rows
2025-04-23 20:57:50,532 - INFO - __main__ - Chunk size: 3000, Overlap: 70, Effective chunk size: 2930
2025-04-23 20:57:50,533 - INFO - __main__ - Processing chunk 1/7: rows 0 to 3000
2025-04-23 20:57:50,533 - INFO - __main__ - Chunk 1 size: 3000 rows
2025-04-23 20:57:50,533 - INFO - __main__ - Skipping first chunk as it was used for initialization
2025-04-23 20:57:50,534 - INFO - __main__ - Processing chunk 2/7: rows 2930 to 5930
2025-04-23 20:57:50,534 - INFO - __main__ - Chunk 2 size: 3000 rows
2025-04-23 20:57:55,206 - INFO - __main__ - Created 2931 sequences from chunk 2
2025-04-23 20:57:55,223 - INFO - __main__ - Chunk 2 data shapes - X_train: (2344, 60, 19), y_train: (2344, 10)
2025-04-23 20:57:55,223 - INFO - __main__ - Training on chunk 2
2025-04-23 20:57:55,224 - INFO - __main__ - Using 12 epochs for training on chunk 2
2025-04-23 21:03:37,661 - INFO - __main__ - Chunk 2 validation - Loss: 0.005758248269557953, MAE: 0.05717617645859718
2025-04-23 21:03:38,106 - INFO - __main__ - Processing chunk 3/7: rows 5860 to 8860
2025-04-23 21:03:38,107 - INFO - __main__ - Chunk 3 size: 3000 rows
2025-04-23 21:03:43,233 - INFO - __main__ - Created 2931 sequences from chunk 3
2025-04-23 21:03:43,255 - INFO - __main__ - Chunk 3 data shapes - X_train: (2344, 60, 19), y_train: (2344, 10)
2025-04-23 21:03:43,256 - INFO - __main__ - Training on chunk 3
2025-04-23 21:03:43,256 - INFO - __main__ - Using 12 epochs for training on chunk 3
2025-04-23 21:09:19,577 - INFO - __main__ - Chunk 3 validation - Loss: 0.0037644237745553255, MAE: 0.048416730016469955
2025-04-23 21:09:19,764 - INFO - __main__ - Processing chunk 4/7: rows 8790 to 11790
2025-04-23 21:09:19,765 - INFO - __main__ - Chunk 4 size: 3000 rows
2025-04-23 21:09:24,307 - INFO - __main__ - Created 2931 sequences from chunk 4
2025-04-23 21:09:24,316 - INFO - __main__ - Chunk 4 data shapes - X_train: (2344, 60, 19), y_train: (2344, 10)
2025-04-23 21:09:24,317 - INFO - __main__ - Training on chunk 4
2025-04-23 21:09:24,317 - INFO - __main__ - Using 12 epochs for training on chunk 4
2025-04-23 21:14:59,263 - INFO - __main__ - Chunk 4 validation - Loss: 0.005527385976165533, MAE: 0.05344296246767044
2025-04-23 21:14:59,447 - INFO - __main__ - Processing chunk 5/7: rows 11720 to 14720
2025-04-23 21:14:59,448 - INFO - __main__ - Chunk 5 size: 3000 rows
2025-04-23 21:15:04,211 - INFO - __main__ - Created 2931 sequences from chunk 5
2025-04-23 21:15:04,221 - INFO - __main__ - Chunk 5 data shapes - X_train: (2344, 60, 19), y_train: (2344, 10)
2025-04-23 21:15:04,221 - INFO - __main__ - Training on chunk 5
2025-04-23 21:15:04,222 - INFO - __main__ - Using 12 epochs for training on chunk 5
2025-04-23 21:21:38,906 - INFO - __main__ - Chunk 5 validation - Loss: 0.004427193198353052, MAE: 0.05088381841778755
2025-04-23 21:21:39,141 - INFO - __main__ - Processing chunk 6/7: rows 14650 to 17650
2025-04-23 21:21:39,143 - INFO - __main__ - Chunk 6 size: 3000 rows
2025-04-23 21:21:44,619 - INFO - __main__ - Created 2931 sequences from chunk 6
2025-04-23 21:21:44,628 - INFO - __main__ - Chunk 6 data shapes - X_train: (2344, 60, 19), y_train: (2344, 10)
2025-04-23 21:21:44,629 - INFO - __main__ - Training on chunk 6
2025-04-23 21:21:44,629 - INFO - __main__ - Using 12 epochs for training on chunk 6
2025-04-23 21:28:06,653 - INFO - __main__ - Chunk 6 validation - Loss: 0.003915620967745781, MAE: 0.04736144840717316
2025-04-23 21:28:06,874 - INFO - __main__ - Processing chunk 7/7: rows 17580 to 17961
2025-04-23 21:28:06,875 - INFO - __main__ - Chunk 7 size: 381 rows
2025-04-23 21:28:07,449 - INFO - __main__ - Created 312 sequences from chunk 7
2025-04-23 21:28:07,819 - INFO - __main__ - Chunk 7 data shapes - X_train: (249, 60, 19), y_train: (249, 10)
2025-04-23 21:28:07,820 - INFO - __main__ - Training on chunk 7
2025-04-23 21:28:07,820 - INFO - __main__ - Using 12 epochs for training on chunk 7
2025-04-23 21:28:49,916 - INFO - __main__ - Chunk 7 validation - Loss: 0.002773284912109375, MAE: 0.04075443372130394
2025-04-23 21:28:53,506 - INFO - __main__ - Final evaluation - Loss: 0.03327159583568573, MAE: 0.1513865441083908
2025-04-23 22:02:08,960 - ERROR - __main__ - Unhandled exception: 404 Not Found: The requested URL was not found on the server. If you entered the URL manually please check your spelling and try again.
2025-04-23 22:02:11,806 - ERROR - __main__ - Traceback: Traceback (most recent call last):
  File "/home/olex/.local/lib/python3.8/site-packages/flask/app.py", line 1823, in full_dispatch_request
    rv = self.dispatch_request()
  File "/home/olex/.local/lib/python3.8/site-packages/flask/app.py", line 1788, in dispatch_request
    self.raise_routing_exception(req)
  File "/home/olex/.local/lib/python3.8/site-packages/flask/app.py", line 1770, in raise_routing_exception
    raise request.routing_exception  # type: ignore
  File "/home/olex/.local/lib/python3.8/site-packages/flask/ctx.py", line 351, in match_request
    result = self.url_adapter.match(return_rule=True)  # type: ignore
  File "/home/olex/.local/lib/python3.8/site-packages/werkzeug/routing/map.py", line 624, in match
    raise NotFound() from None
werkzeug.exceptions.NotFound: 404 Not Found: The requested URL was not found on the server. If you entered the URL manually please check your spelling and try again.

